Workbook

Sheet 修正履歴
A1: マスタ定義書
A3: 項番 | B3: Oculus Ver | C3: 修正理由 | D3: 修正対象／修正内容 | E3: 修正完了日 | F3: 修正者
A4: 1 | B4: 5.0 | C4: - | D4: 新規作成 | E4: 43081 | F4: NDLC
A5: 2 | B5: 5.0 | C5: V5開発対応 | D5: ■17_コード設定マスタ ・リストアップロードに関するコードを追加 ■34_リスト処理属性管理 ・今回の対象リストを追加 | E5: 43081 | F5: NDLC
A6: 3 | B6: 5.0 | C6: V5開発対応 | D6: ■15_リスト発行元マスタ ・Phase2時点で使用可能なリスト以外はグレーアウト→グレーアウトを解除 ■16_リスト名マスタ ・Phase2時点で使用可能なリスト以外はグレーアウト→グレーアウトを解除 ■21_リスト登録情報 ・Phase2時点で使用可能なリスト以外はグレーアウト→グレーアウトを解除 ■23_フィルタリング定義マスタ ・Phase2時点で使用可能なリスト以外はグレーアウト→グレーアウトを解除 ・B列に記載されていたpathをv4環境と同じ内容に変更 ■24_リスト切替フィルタリング設定 ・Phase2時点で使用可能なリスト以外はグレーアウト→グレーアウトを解除 ■25_部店フィルタリング設定 ・「15_リスト発行元マスタ」の変更に伴い修正 ■26_CIFファイルフィルタリング設定 ・「15_リスト発行元マスタ」の変更に伴い修正 ■28_シミュレーション定義マスタ ・「15_リスト発行元マスタ」の変更に伴い修正 ・B列に記載されていたpathをv4環境と同じ内容に変更 ■29_リスト権限マスタ ・Phase2時点で使用可能なリスト以外はグレーアウト→グレーアウトを解除 ■30_取引リスト表示管理 ・「15_リスト発行元マスタ」の変更に伴い追記 | E6: 45583 | F6: 貝塚
A7: 4 | B7: 5.0 | C7: V5開発対応 | D7: ■8_取引マスタ ・DEAL_ID No.37行追加 ■9_操作マスタ ・OPE_ID No.179、No.180行追加 ■10_実行権限マスタ ・EXEC_AUTH_ID No.63行追加 ■11_プロファイル設定 ・EXEC_AUTH_ID No.63行追加 ■40_運用ファイルアップロード管理 ・シート追加 | E7: 45595 | F7: 王セイテイ
A8: 5 | B8: 5.0 | C8: V5開発対応 | D8: ■テーブル一覧 ・「備考」欄を「設定方法」に変更 ・「運用ファイルアップロード管理」の設定方法欄を修正 ■41_IPアドレス管理 ・シート追加（V4からの復元） ■40_運用ファイルアップロード管理 ・SQLおよび比較欄の数式を修正 | E8: 45602 | F8: 齋藤奈々
A9: 6 | B9: 5.0 | C9: V5開発対応 | D9: ■35_リスト取込マスタ ・リストID:1～13を追加（ORG1リスト以外の設定） | E9: 45606 | F9: 齋藤奈々
A10: 7 | B10: 5.0 | C10: V5開発対応 | D10: ■テーブル一覧 ・AML・SIMで必要なtblを確認できるように列を追加 ■リスト登録情報 ・「FILE_UPDATE_DATE」カラムを追加 ■操作マスタ ・OPR_ID OPE_NAME 97 登録 98 解除 99 戻る 上記レコードのWIN_NAMEを「シミュレーションフィルタリング予約」→「シミュレーション予約画面」に変更 ■40_運用ファイルアップロード管理 ・「O:\TEMP\MASTER_MAINTENANCE\aml01」→「O:\TEMP\MASTER_MAINTENANCE」に変更 | E10: 45607 | F10: 貝塚瞬
A11: 8 | B11: 5.0 | C11: V5開発対応 | D11: ■15_リスト発行元マスタ ・「THRESHOLD」カラムを追加 | E11: 45608 | F11: 高 博
A12: 9 | B12: 5.0 | C12: V5開発対応 | D12: ■8_取引マスタ ・DEAL_ID:16 (共通リスト登録日照会)を不可→未使用に変更 ※廃止された画面のため ■9_操作マスタ ・OPE_ID:60 (判定済照会.判定済一覧画面.ファイル出力)を未使用→不可に変更 ・OPE_ID:83 (メニュー.共通リスト登録日照会)を不可→未使用に変更 ※廃止された画面のため ・OPE_ID:116(登録済リスト履歴一覧画面.クリア)を不可→未使用に変更 ※OPE_IDが利用されていないため ・OPE_ID:117(登録済リスト履歴一覧画面.編集)を不可→未使用に変更 ※廃止されたボタンのため ・OPE_ID:137(ホワイトリスト登録・削除画面.クリア)を不可→未使用に変更 ※OPE_IDが利用されていないため | E12: 45611 | F12: 益田 慧
A13: 10 | B13: 5.0 | C13: V5開発対応 | D13: ■32_リスト検索項目管理 ・LST＿IDが1～4,6～13の項目を追加 | E13: 45612 | F13: 貝塚 瞬
A14: 11 | B14: 5.0 | C14: V5開発対応 | D14: ■35_リスト取込マスタ ・LST_ID：6の「C:\LIST_BATCH\bin\ListFormatUp.bat MOF OFF OFF」へ修正 ・LST_ID：7の「C:\LIST_BATCH\bin\ListFormatUp.bat MOF OFF OFF」へ修正 ・LST_ID：7の「C:\LIST_BATCH\bin\MergeNames.bat PEPs_ORG.csv JP.csv OFF」を削除 ・LST_ID：8の「C:\LIST_BATCH\bin\ListFormatUp.bat JU OFF OFF」へ修正 ・LST_ID：8の「C:\LIST_BATCH\bin\MergeNames.bat UN_ORG.csv JU.csv OFF」を削除 ・LST_ID：9の「C:\LIST_BATCH\bin\ListFormatUp.bat NPA OFF OFF」へ修正 ・LST_ID：10の「C:\LIST_BATCH\bin\ListFormatUp.bat NPC OFF OFF」へ修正 ・LST_ID：11の「C:\LIST_BATCH\bin\ListFormatUp.bat NPI OFF OFF」へ修正 ・LST_ID：12の「C:\LIST_BATCH\bin\ListFormatUp.bat ASI OFF OFF」へ修正 ・LST_ID：12の「C:\LIST_BATCH\bin\GrantID.bat ASI_ORG.csv ASI.csv I」を削除 ・LST_ID：13の「C:\LIST_BATCH\bin\ListFormatUp.bat ASC OFF OFF」へ修正 ・LST_ID：13の「C:\LIST_BATCH\bin\GrantID.bat ASC_ORG.csv ASC.csv C」を削除 ・LST_ID：14の「C:\LIST_BATCH\bin\ListFormatUp.bat ORG1 OFF OFF」へ修正 | E14: 45615 | F14: 趙
A15: 12 | B15: 5.0 | C15: V5開発対応 | D15: ■14_通番管理 ・SEQ_NO_NAMEがバッチリストアップロードIDの項目を追加 | E15: 45615 | F15: 高 博
... A53: 50 | B53: 5.0 | C53: 設定不備 | D53: ■14_通番管理 「SEQ_NO_NAME」=「検索対象者一覧ファイル」の値を「一括フィルタリング」に修正 ■28_シミュレーション定義マスタ 「COMBI_FILE_BATCH」に記載したパスが間違ったため、下記のように修正。 修正前：C:\sim_filter\parm\batch\amlxx\～～ 修正後：C:\sim_filter\parm\amlxx\～～ | E53: 45673 | F53: 諸
A54: =ROW()-3 -> 51 | B54: 5.0 | C54: 画面アップロード対象のリスト設定内容変更 | D54: ■34_リスト処理属性管理 ・LST_ID=1～3、9～12、15のレコードのRSV_FLG1を1に修正。 | E54: 45691 | F54: 諸
A55: =ROW()-3 -> 52 | B55: 5.0 | C55: 登録済リスト参照画面の表示不具合対応 | D55: ■21_リスト登録情報 ・各リストのおける初期値を登録 | E55: 45692 | F55: 細井
A56: =ROW()-3 -> 53 | B56: 5.0 | C56: 「運用ファイルアップロード」画面の非表示対応 | D56: ■11_プロファイル設定 ・"EXEC_AUTH_ID=63"のレコード削除 | E56: 45715 | F56: 細井
A57: =ROW()-3 -> 54 | B57: 5.0 | C57: V5開発対応 | D57: ■14_通番管理 以下のレコードはPKG標準では不要のため削除。 ・FACTIVA_SANC ・ORG | E57: 45664 | F57: 齋藤奈々
A58: =ROW()-3 -> 55 | B58: 5.0 | C58: V5開発対応 CR-0018不具合対応 | D58: ①■10_実行権限マスタ 8_取引マスタのDEAL_ID=16(共通リスト登録日照会)を削除したのでそれに伴い下記を削除 DEAL_ID=16(共通リスト登録日照会) ②■21_リスト登録情報 LST_ID=1のレコードのHST_SAVE_MONTH=60→HST_SAVE_MONTH=12に変更 | E58: 45678 | F58: 貝塚瞬
A59: =ROW()-3 -> 56 | B59: 5.0 | C59: V5開発対応 ∟OFV5.0-CR-0018_差分フィルタリング仕様変更 | D59: ■12_ファイル属性管理 以下のカラムのデフォルト値をNからYへ変更 PAST_APPLY_TYPE、FORCE_PAST_FLAG | E59: 45673 | F59: 趙
A60: =ROW()-3 -> 57 | B60: 5.0 | C60: V5開発対応 ∟OFV5.0-CR-0019_DJ制裁者リスト夜間取込の差分対応 | D60: ■34_リスト処理属性管理 LST_ID=4のレコードのFILE_NAME=dowjones.xml→FILE_NAME=dowjones_peps.xmlに変更 | E60: 45694 | F60: 齋藤奈々
A61: =ROW()-3 -> 58 | B61: 5.0 | C61: 検索対象者中断処理対応 | D61: ■36_バッチフィルタリング中断管理 SEARCH_BAT_SAS_FLG 追加 | E61: 2024/12/26 (2025/2/13) | F61: 官 (田中 伶奈 マージ対応)
A62: =ROW()-3 -> 59 | B62: 5.0 | C62: SI設定修正 | D62: ■23_フィルタリング定義マスタ ■28_シミュレーション定義マスタ ・OFACウォッチリスト名を「OFC」⇒「OFAC」に修正 | E62: 45734 | F62: 諸
A63: =ROW()-3 -> 60 | B63: 5.0 | C63: SI設定修正 | D63: ■5_部店マスタ 「全ての部店」のUNIT_CODEを001⇒9999に修正 | E63: 45769 | F63: 細井
A64: =ROW()-3 -> 61 | B64: 5.0 | C64: 自動DLリスト連携対象リストのWEBアップロード | D64: ■34_リスト処理属性管理 LST_ID「1」、「2」、「3」、「9」、「10」、「11」、「12」のRSV_FLG1「1」⇒「0」に修正 LST_ID「9」、「10」、「11」、「12」のUPD_TYPE_SET_FLG「1」⇒「2」に修正 | E64: 45826 | F64: 田中
A65: =ROW()-3 -> 62 | B65: 5.0 | C65: V5開発対応 OFV5.0-CR-0039_未判定放置不具合 | D65: ■12_ファイル属性管理 検索対象者一覧ファイルは過去判定をする必要がないため、下記の設定値をY→Nに修正。 PAST_APPLY_TYPE, FORCE_PAST_FLAG | E65: 45771 | F65: 齋藤奈々
A66: =ROW()-3 -> 63 | B66: 5.0 | C66: リストアップロード時処理結果出力 | D66: ■34_リスト処理属性管理 LST_ID「1」、「9」、「10」、「11」、「12」のRSV_FLG2「3」⇒「2」に修正 | E66: 45828 | F66: 田中
A67: =ROW()-3 -> 64 | B67: 5.0 | C67: 利用リスト変更対応 | D67: 以下のシートに記載をJU→MOFに修正 15_リスト発行元マスタ 23_フィルタリング定義マスタ 28_シミュレーション定義マスタ 34_リスト処理属性管理 35_リスト取込マスタ | E67: 45831 | F67: 品川
A68: =ROW()-3 -> 65 | B68: 5.0 | C68: 部店変更 | D68: ■5_部店マスタ UNIT_CODE「00001」削除 UNIT_CODE「11100」、「12008」、「13606」、「91510」追加 UNIT_CODE「14800」のUNIT_NAME「ＩＣＴ推進部」⇒「ＩＴソリューション部」に修正 UNIT_CODE「14801」のUNIT_NAME「ＩＣＴ推進部セキュリティ統括室」⇒「ＩＴソリューション部セキュリティ統括室」に修正 ■25_部店フィルタリング設定 UNIT_ID「272」削除 UNIT_ID「560」「561」「562」「563」追加 | E68: 45882 | F68: 田中
A69: =ROW()-3 -> 66 | B69: 5.0 | C69: ファイル属性追加 | D69: ■10_実行権限マスタ EXEC_AUTH_ID「521」～「523」のEXEC_AUTH_NAME「一括フィルタリング」→「一括フィルタリング①」に変更 EXEC_AUTH_ID「524」～「550」を追加 ■11_プロファイル設定 PRF_ID「2」のEXEC_AUTH_ID「524」～「550」追加 PRF_ID「3」のEXEC_AUTH_ID「524」～「550」追加 PRF_ID「4」のEXEC_AUTH_ID「524」～「549」追加 ※「526」、「529」、「532」、「535」、「538」、「541」、「544」、「547」を除く PRF_ID「5」のEXEC_AUTH_ID「524」～「549」追加 ※「526」、「529」、「532」、「535」、「538」、「541」、「544」、「547」を除く ■12_ファイル属性管理 FILE_ATTR「E」のDISP_NAME「一括フィルタリング」→「一括フィルタリング①」に変更 FILE_ATTR「F」～「N」を追加 ■13_ファイル属性設定 EXEC_AUTH_ID「524」～「550」を追加 ■14_通番管理 SEQ_NO_NAME「一括フィルタリング」→「一括フィルタリング①」に変更 SEQ_NO_NAME「一括フィルタリング②～⑩」を追加 ■26_CIFファイルフィルタリング設定 FILE_ATTR「F」～「N」を追加 | E69: 45882 | F69: 田中
A70: =ROW()-3 -> 67 | B70: 5.0 | C70: 部店追加 | D70: ■5_部店マスタ UNIT_CODE「testA」、「testB」、「testC」、「testE」、「testF」追加 ■25_部店フィルタリング設定 UNIT_ID「555」「556」「557」「558」「559」追加 | E70: 45890 | F70: 三國
A71: =ROW()-3 -> 68 | B71: 5.0 | C71: プロファイル追加 | D71: ■1_プロファイルマスタ PRF_ID「8」追加 | E71: 45957 | F71: 田中
A72: =ROW()-3 -> 69 | B72: 5.0 | C72: 部店追加 | D72: ■5_部店マスタ UNIT_CODE「12009」、「13101」、「13102」、「13103」、「13815」、「13906」、「14104」、「14110」、「14201」、「14900」、「15007」、「15008」、「15009」、「99963」追加 UNIT_CODE「13902」、「13903」、「13905」、「14801」、「15005」削除 UNIT_CODE「14100」のUNIT_NAME「デジタル戦略部」⇒「リテール戦略部」に修正 UNIT_CODE「14101」のUNIT_NAME「デジタル戦略部決済ビジネス戦略室」⇒「リテール戦略部法人マーケティング室」に修正 UNIT_CODE「14102」のUNIT_NAME「デジタル戦略部マーケティング戦略室」⇒「リテール戦略部個人マーケティング室」に修正 UNIT_CODE「99962」のUNIT_NAME「コンコルディアＦＧ」⇒「横浜ＦＧ」に修正 ■25_部店フィルタリング設定 UNIT_ID「564」、「565」、「566」、「567」、「568」、「569」、「570」、「571」、「572」、「573」、「574」、「575」、「576」、「577」追加 UNIT_ID「299」、「300」、「302」、「310」、「314」削除 | E72: 46119 | F72: 阿部
A73: =ROW()-3 -> 70 | B73: 5.0 | C73: 警察庁リスト統合対応 | D73: ■24_リスト切替フィルタリング設定、25_部店フィルタリング設定、26_CIFファイルフィルタリング設定 FILTERING_DEF_ID「6」を削除 ■23_フィルタリング定義マスタ NPIのIS_ONLY_BATCHを「Y」に変更 ■29_リスト権限マスタ NPIのLIST_UPLOAD_AUTHを「N」に変更 | E73: 46125 | F73: 三國
A74: =ROW()-3 -> 71 | B74: 5.0 | C74: L&F対応 | D74: プロファイルの追加・リスト追加・部店追加について下記を修正 1_プロファイルマスタ、5_部店マスタ、10_実行権限マスタ、11_プロファイル設定、12_ファイル属性管理、13_ファイル属性設定、14_通番管理、15_リスト発行元マスタ、16_リスト名マスタ、17_コード設定マスタ、21_リスト登録情報、23_フィルタリング定義マスタ、25_部店フィルタリング設定、26_CIFファイルフィルタリング設定、28_シミュレーション定義マスタ、29_リスト権限マスタ、30_取引リスト表示管理、32_リスト検索項目管理、34_リスト処理属性管理、35_リスト取込マスタ | E74: 46252 | F74: 阿部
A75: =ROW()-3 -> 72

Sheet テーブル一覧
E1: ※基本設計書「【別冊】マスターデータ」にプログラムで固定参照する定義が存在しているもの。
B2: マスターデータ テーブル | E2: 別冊 | F2: AML | G2: SIM | H2: 設定方法
B3: 1 | C3: MST_PRF_TBL | D3: プロファイルマスタ | E3: 〇 | F3: 〇 | H3: 導入時にヒアリングで決定。
B4: 2 | C4: MST_USER_TBL | D4: ユーザマスタ | E4: 〇 | F4: 〇 | H4: PKG標準の初期登録ユーザのみ追加。
B5: 3 | C5: HST_PWD_TBL | D5: パスワード履歴 | E5: 〇 | F5: 〇 | H5: PKG標準の初期登録ユーザのみ追加。
B6: 4 | C6: MNG_CONN_TBL | D6: 接続状態管理 | E6: 〇 | F6: 〇 | H6: PKG標準の初期登録ユーザのみ追加。
B7: 5 | C7: MST_UNIT_TBL | D7: 部店マスタ | E7: 〇 | F7: 〇 | G7: 〇 | H7: 導入時にヒアリングで決定。
B8: 6 | C8: CNF_UNIT_TBL | D8: ユーザ部店設定 | E8: 〇 | F8: 〇 | H8: PKG標準の初期登録ユーザのみ追加。
B9: 7 | C9: MST_DEAL_TYPE_TBL | D9: 取引分類マスタ | E9: 〇 | F9: 〇 | H9: PKG標準は固定。
B10: 8 | C10: MST_DEAL_TBL | D10: 取引マスタ | E10: 〇 | F10: 〇 | H10: PKG標準は固定。
B11: 9 | C11: MST_OPE_TBL | D11: 操作マスタ | E11: 〇 | F11: 〇 | H11: PKG標準は固定。
B12: 10 | C12: MST_AUTH_TBL | D12: 実行権限マスタ | E12: 〇 | F12: 〇 | H12: 導入時にヒアリングで追加する項目あり。
B13: 11 | C13: CNF_PRF_TBL | D13: プロファイル設定 | E13: 〇 | F13: 〇 | H13: 導入時にヒアリングで決定。
B14: 12 | C14: FILE_ATTR_TBL | D14: ファイル属性管理 | F14: 〇 | G14: 〇 | H14: 導入時にヒアリングで決定。
B15: 13 | C15: FILE_ATTR_PRF_TBL | D15: ファイル属性設定 | F15: 〇 | H15: 導入時にヒアリングで決定。
B16: 14 | C16: MNG_SEQ_NO_TBL | D16: 通番管理 | E16: 〇 | F16: 〇 | H16: 導入時にヒアリングで追加する項目あり。
B17: 15 | C17: MST_LSTORIGIN_TBL | D17: リスト発行元マスタ | F17: 〇 | G17: 〇 | H17: 導入時にヒアリングで決定。
B18: 16 | C18: MST_LSTDESIGNATION_TBL | D18: リスト名マスタ | F18: 〇 | H18: 導入時にヒアリングで決定。
B19: 17 | C19: MST_CODE_TBL | D19: コード設定マスタ | E19: 〇 | F19: 〇 | H19: 導入時にヒアリングで決定。
B20: 18 | C20: CNF_SEC_TBL | D20: セキュリティ設定 | E20: 〇 | F20: 〇 | H20: 導入時にヒアリングで決定。
B21: 19 | C21: MST_WAREKI_SEIREKI_TBL | D21: 和暦西暦対応 | E21: 〇 | F21: 〇 | H21: PKG標準は固定。
B22: 20 | C22: MST_BUSINESS_TBL | D22: 業務マスタ | F22: 〇 | H22: 導入時にヒアリングで決定。
B23: 21 | C23: LST_REG_TBL | D23: リスト登録情報 | F23: 〇 | H23: 導入時にヒアリングしたリストに対し、初期登録が必要。
B24: 22 | C24: MST_FILTERING_LIST_TBL | D24: フィルタリング対象リストマスタ | F24: 〇 | H24: 導入時にヒアリングで決定。
B25: 23 | C25: MST_FILTERING_DEF_TBL | D25: フィルタリング定義マスタ | F25: 〇 | G25: 〇 | H25: 導入時にヒアリングで決定。
B26: 24 | C26: CNF_LIST_FILTERING_TBL | D26: リスト切替フィルタリング設定 | F26: 〇 | H26: 導入時にヒアリングで決定。
B27: 25 | C27: CNF_UNIT_FILTERING_TBL | D27: 部店フィルタリング設定 | F27: 〇 | H27: 導入時にヒアリングで決定。
B28: 26 | C28: CNF_CIF_FILE_FILTERING_TBL | D28: CIFファイルフィルタリング設定 | F28: 〇 | G28: 〇 | H28: 導入時にヒアリングで決定。
B29: 27 | C29: CNF_DIVIDE_STRINGS_TBL | D29: 分割文字列マスタ | F29: 〇 | H29: 導入時にヒアリングで決定。
B30: 28 | C30: MST_SIM_DEF_TBL | D30: シミュレーション定義マスタ | F30: 〇 | G30: 〇 | H30: 導入時にヒアリングで決定。
B31: 29 | C31: MST_LIST_AUTH_TBL | D31: リスト権限マスタ | F31: 〇 | H31: 導入時にヒアリングしたプロファイルおよびリストに対し、初期登録が必要。
B32: 30 | C32: MNG_DEAL_LIST_DSP_TBL | D32: 取引リスト表示管理 | F32: 〇 | H32: 導入時にヒアリングしたプロファイルおよびリストに対し、初期登録が必要。
B33: 31 | C33: MNG_LIST_REF_TBL | D33: リスト補足管理 | F33: 〇 | H33: 導入時にヒアリングで決定。
B34: 32 | C34: MNG_LIST_SEARCH_ITEM_TBL | D34: リスト検索項目管理 | F34: 〇 | H34: 導入時にヒアリングしたリストに対し、初期登録が必要。
B35: 33 | C35: MNG_LIST_DUPE_ITEM_TBL | D35: リスト重複チェック項目管理 | F35: 〇 | H35: PKG標準は固定。（一律登録なし）
B36: 34 | C36: MNG_LIST_ATTR_TBL | D36: リスト処理属性管理 | F36: 〇 | H36: 導入時にヒアリングしたリストに対し、初期登録が必要。
B37: 35 | C37: MST_LIST_IMP_TBL | D37: リスト取込マスタ | F37: 〇 | H37: 導入時にヒアリングしたリストに対し、初期登録が必要。
B38: 36 | C38: MNG_BAT_SUSPEND_TBL | D38: バッチフィルタリング中断管理 | F38: 〇 | H38: 処理サーバ数に合わせて、初期登録が必要。
B39: 37 | C39: CNF_NUMBERING_ASSISTANCE_CODE_TBL | D39: 採番補助コード設定 | F39: 〇 | H39: PKG標準は固定。（一律登録なしだがTBLは必要。）
B40: 38 | C40: MNG_OPE_FILE_UPLOAD_TBL | D40: 運用ファイルアップロード管理 | F40: 〇 | H40: PKG標準は固定。
...

Sheet 1_プロファイルマスタ
A1: パッケージ標準 | G1: 一覧へ | H1: 横浜銀行様用出荷設定 | N1: SQL | T1: PRF_ID | U1: PRF_CODE | V1: PRF_NAME | W1: PRF_TYPE | X1: LAST_UPDATE_DATE
A2: PRF_ID | B2: PRF_CODE | C2: PRF_NAME | D2: PRF_TYPE | E2: LAST_UPDATE_DATE | F2: 構築資材 | G2: 変更可否 | H2: PRF_ID | I2: PRF_CODE | J2: PRF_NAME | K2: PRF_TYPE | L2: LAST_UPDATE_DATE | N2: 固定 | O2: 固定 | P2: 固定 | Q2: 数式 | R2: 固定 | T2: 数式 | U2: 数式 | V2: 数式 | W2: 数式 | X2: 数式
A3: 1 | B3: 0001 | C3: セキュリティ管理者 | D3: K | E3: 2018/01/01 00:00:00 | F3: 〇 | G3: 不可 | H3: 1 | I3: 0001 | J3: セキュリティ管理者 | K3: K | L3: 2018/01/01 00:00:00 | N3: INSERT INTO | O3: MST_PRF_TBL | P3: VALUES( | Q3: =H3&" , "&"'"&I3&"'"&" , "&"'"&J3&"'"&" , "&"'"&K3&"'"&" , "&"to_timestamp('"&L3&"'"&" , "&"'yyyy/MM/dd hh24:mi:ss')" -> 1 , '0001' , 'セキュリティ管理者' , 'K' , to_timestamp('2018/01/01 00:00:00' , 'yyyy/MM/dd hh24:mi:ss') | R3: ); | T3: =IF(H3="","",EXACT(H3,Z3)) -> FALSE | U3: =IF(I3="","",EXACT(I3,AA3)) -> FALSE | V3: =IF(J3="","",EXACT(J3,AB3)) -> FALSE | W3: =IF(K3="","",EXACT(K3,AC3)) -> FALSE | X3: =IF(L3="","",EXACT(L3,AD3)) -> FALSE
A4: 2 | B4: 0002 | C4: 管理者(全店) | D4: K | E4: 2018/01/01 00:00:00 | F4: 〇 | G4: 可 | H4: 2 | I4: 0002 | J4: リスク管理部門（役席） | K4: K | L4: 2018/01/01 00:00:00 | N4: INSERT INTO | O4: MST_PRF_TBL | P4: VALUES( | Q4: =H4&" , "&"'"&I4&"'"&" , "&"'"&J4&"'"&" , "&"'"&K4&"'"&" , "&"to_timestamp('"&L4&"'"&" , "&"'yyyy/MM/dd hh24:mi:ss')" -> 2 , '0002' , 'リスク管理部門（役席）' , 'K' , to_timestamp('2018/01/01 00:00:00' , 'yyyy/MM/dd hh24:mi:ss') | R4: ); | T4: =IF(H4="","",EXACT(H4,Z4)) -> FALSE | U4: =IF(I4="","",EXACT(I4,AA4)) -> FALSE | V4: =IF(J4="","",EXACT(J4,AB4)) -> FALSE | W4: =IF(K4="","",EXACT(K4,AC4)) -> FALSE | X4: =IF(L4="","",EXACT(L4,AD4)) -> FALSE
A5: 3 | B5: 0003 | C5: 管理者(自店) | D5: P | E5: 2018/01/01 00:00:00 | F5: 〇 | G5: 可 | H5: 3 | I5: 0003 | J5: リスク管理部門（担当） | K5: P | L5: 2018/01/01 00:00:00 | N5: INSERT INTO | O5: MST_PRF_TBL | P5: VALUES( | Q5: =H5&" , "&"'"&I5&"'"&" , "&"'"&J5&"'"&" , "&"'"&K5&"'"&" , "&"to_timestamp('"&L5&"'"&" , "&"'yyyy/MM/dd hh24:mi:ss')" -> 3 , '0003' , 'リスク管理部門（担当）' , 'P' , to_timestamp('2018/01/01 00:00:00' , 'yyyy/MM/dd hh24:mi:ss') | R5: ); | T5: =IF(H5="","",EXACT(H5,Z5)) -> FALSE | U5: =IF(I5="","",EXACT(I5,AA5)) -> FALSE | V5: =IF(J5="","",EXACT(J5,AB5)) -> FALSE | W5: =IF(K5="","",EXACT(K5,AC5)) -> FALSE | X5: =IF(L5="","",EXACT(L5,AD5)) -> FALSE
A6: 4 | B6: 0004 | C6: 担当者(判定権限あり) | D6: P | E6: 2018/01/01 00:00:00 | F6: 〇 | G6: 可 | H6: 4 | I6: 0004 | J6: その他部門（役席） | K6: P | L6: 2018/01/01 00:00:00 | N6: INSERT INTO | O6: MST_PRF_TBL | P6: VALUES( | Q6: =H6&" , "&"'"&I6&"'"&" , "&"'"&J6&"'"&" , "&"'"&K6&"'"&" , "&"to_timestamp('"&L6&"'"&" , "&"'yyyy/MM/dd hh24:mi:ss')" -> 4 , '0004' , 'その他部門（役席）' , 'P' , to_timestamp('2018/01/01 00:00:00' , 'yyyy/MM/dd hh24:mi:ss') | R6: ); | T6: =IF(H6="","",EXACT(H6,Z6)) -> FALSE | U6: =IF(I6="","",EXACT(I6,AA6)) -> FALSE | V6: =IF(J6="","",EXACT(J6,AB6)) -> FALSE | W6: =IF(K6="","",EXACT(K6,AC6)) -> FALSE | X6: =IF(L6="","",EXACT(L6,AD6)) -> FALSE
A7: 5 | B7: 0005 | C7: 担当者(判定権限なし) | D7: P | E7: 2018/01/01 00:00:00 | F7: 〇 | G7: 可 | H7: 5 | I7: 0005 | J7: その他部門（担当） | K7: P | L7: 2018/01/01 00:00:00 | N7: INSERT INTO | O7: MST_PRF_TBL | P7: VALUES( | Q7: =H7&" , "&"'"&I7&"'"&" , "&"'"&J7&"'"&" , "&"'"&K7&"'"&" , "&"to_timestamp('"&L7&"'"&" , "&"'yyyy/MM/dd hh24:mi:ss')" -> 5 , '0005' , 'その他部門（担当）' , 'P' , to_timestamp('2018/01/01 00:00:00' , 'yyyy/MM/dd hh24:mi:ss') | R7: ); | T7: =IF(H7="","",EXACT(H7,Z7)) -> FALSE | U7: =IF(I7="","",EXACT(I7,AA7)) -> FALSE | V7: =IF(J7="","",EXACT(J7,AB7)) -> FALSE | W7: =IF(K7="","",EXACT(K7,AC7)) -> FALSE | X7: =IF(L7="","",EXACT(L7,AD7)) -> FALSE
A8: 6 | B8: 0006 | C8: シミュレーション管理者 | D8: P | E8: 2018/01/01 00:00:00 | F8: 〇 | G8: 可 | H8: 6 | I8: 0006 | J8: シミュレーション管理者 | K8: P | L8: 2018/01/01 00:00:00 | N8: INSERT INTO | O8: MST_PRF_TBL | P8: VALUES( | Q8: =H8&" , "&"'"&I8&"'"&" , "&"'"&J8&"'"&" , "&"'"&K8&"'"&" , "&"to_timestamp('"&L8&"'"&" , "&"'yyyy/MM/dd hh24:mi:ss')" -> 6 , '0006' , 'シミュレーション管理者' , 'P' , to_timestamp('2018/01/01 00:00:00' , 'yyyy/MM/dd hh24:mi:ss') | R8: ); | T8: =IF(H8="","",EXACT(H8,Z8)) -> FALSE | U8: =IF(I8="","",EXACT(I8,AA8)) -> FALSE | V8: =IF(J8="","",EXACT(J8,AB8)) -> FALSE | W8: =IF(K8="","",EXACT(K8,AC8)) -> FALSE | X8: =IF(L8="","",EXACT(L8,AD8)) -> FALSE
A9: 7 | B9: 0007 | C9: シミュレーション担当者 | D9: P | E9: 2018/01/01 00:00:00 | F9: 〇 | G9: 可 | H9: 7 | I9: 0007 | J9: シミュレーション担当者 | K9: P | L9: 2018/01/01 00:00:00 | N9: INSERT INTO | O9: MST_PRF_TBL | P9: VALUES( | Q9: =H9&" , "&"'"&I9&"'"&" , "&"'"&J9&"'"&" , "&"'"&K9&"'"&" , "&"to_timestamp('"&L9&"'"&" , "&"'yyyy/MM/dd hh24:mi:ss')" -> 7 , '0007' , 'シミュレーション担当者' , 'P' , to_timestamp('2018/01/01 00:00:00' , 'yyyy/MM/dd hh24:mi:ss') | R9: ); | T9: =IF(H9="","",EXACT(H9,Z9)) -> FALSE | U9: =IF(I9="","",EXACT(I9,AA9)) -> FALSE | V9: =IF(J9="","",EXACT(J9,AB9)) -> FALSE | W9: =IF(K9="","",EXACT(K9,AC9)) -> FALSE | X9: =IF(L9="","",EXACT(L9,AD9)) -> FALSE
H10: 8 | I10: 0008 | J10: ロールなし | K10: P | L10: 2018/01/01 00:00:00 | N10: INSERT INTO | O10: MST_PRF_TBL | P10: VALUES( | Q10: =H10&" , "&"'"&I10&"'"&" , "&"'"&J10&"'"&" , "&"'"&K10&"'"&" , "&"to_timestamp('"&L10&"'"&" , "&"'yyyy/MM/dd hh24:mi:ss')" -> 8 , '0008' , 'ロールなし' , 'P' , to_timestamp('2018/01/01 00:00:00' , 'yyyy/MM/dd hh24:mi:ss') | R10: ); | T10: =IF(H10="","",EXACT(H10,Z10)) -> FALSE | U10: =IF(I10="","",EXACT(I10,AA10)) -> FALSE | V10: =IF(J10="","",EXACT(J10,AB10)) -> FALSE | W10: =IF(K10="","",EXACT(K10,AC10)) -> FALSE | X10: =IF(L10="","",EXACT(L10,AD10)) -> FALSE
H11: 9 | I11: 0009 | J11: L＆F管理者（リスク管理部） | K11: P | L11: 2026/12/24 00:00:00 | N11: INSERT INTO | O11: MST_PRF_TBL | P11: VALUES( | Q11: =H11&" , "&"'"&I11&"'"&" , "&"'"&J11&"'"&" , "&"'"&K11&"'"&" , "&"to_timestamp('"&L11&"'"&" , "&"'yyyy/MM/dd hh24:mi:ss')" -> 9 , '0009' , 'L＆F管理者（リスク管理部）' , 'P' , to_timestamp('2026/12/24 00:00:00' , 'yyyy/MM/dd hh24:mi:ss') | R11: ); | T11: =IF(H11="","",EXACT(H11,Z11)) -> FALSE | U11: =IF(I11="","",EXACT(I11,AA11)) -> FALSE | V11: =IF(J11="","",EXACT(J11,AB11)) -> FALSE | W11: =IF(K11="","",EXACT(K11,AC11)) -> FALSE | X11: =IF(L11="","",EXACT(L11,AD11)) -> FALSE
H12: 10 | I12: 0010 | J12: L＆F管理者（リスク管理部以外） | K12: P | L12: 2026/12/24 00:00:00 | N12: INSERT INTO | O12: MST_PRF_TBL | P12: VALUES( | Q12: =H12&" , "&"'"&I12&"'"&" , "&"'"&J12&"'"&" , "&"'"&K12&"'"&" , "&"to_timestamp('"&L12&"'"&" , "&"'yyyy/MM/dd hh24:mi:ss')" -> 10 , '0010' , 'L＆F管理者（リスク管理部以外）' , 'P' , to_timestamp('2026/12/24 00:00:00' , 'yyyy/MM/dd hh24:mi:ss') | R12: ); | T12: =IF(H12="","",EXACT(H12,Z12)) -> FALSE | U12: =IF(I12="","",EXACT(I12,AA12)) -> FALSE | V12: =IF(J12="","",EXACT(J12,AB12)) -> FALSE | W12: =IF(K12="","",EXACT(K12,AC12)) -> FALSE | X12: =IF(L12="","",EXACT(L12,AD12)) -> FALSE
H13: 11 | I13: 0011 | J13: L&F担当者 | K13: P | L13: 2026/12/24 00:00:00 | N13: INSERT INTO | O13: MST_PRF_TBL | P13: VALUES( | Q13: =H13&" , "&"'"&I13&"'"&" , "&"'"&J13&"'"&" , "&"'"&K13&"'"&" , "&"to_timestamp('"&L13&"'"&" , "&"'yyyy/MM/dd hh24:mi:ss')" -> 11 , '0011' , 'L&F担当者' , 'P' , to_timestamp('2026/12/24 00:00:00' , 'yyyy/MM/dd hh24:mi:ss') | R13: ); | T13: =IF(H13="","",EXACT(H13,Z13)) -> FALSE | U13: =IF(I13="","",EXACT(I13,AA13)) -> FALSE | V13: =IF(J13="","",EXACT(J13,AB13)) -> FALSE | W13: =IF(K13="","",EXACT(K13,AC13)) -> FALSE | X13: =IF(L13="","",EXACT(L13,AD13)) -> FALSE

Sheet 2_ユーザマスタ
A1: パッケージ標準 | J1: 一覧へ | K1: ='1_プロファイルマスタ'!$H$1 -> 横浜銀行様用出荷設定 | T1: SQL
A2: USER_ID | B2: USER_CODE | C2: USER_NAME | D2: PRF_ID | E2: IS_LOCK | F2: IS_DEL | G2: CREATE_DATE | H2: LAST_UPDATE_DATE | I2: 構築資材 | J2: 変更可否 | K2: USER_ID | L2: USER_CODE | M2: USER_NAME | N2: PRF_ID | O2: IS_LOCK | P2: IS_DEL | Q2: CREATE_DATE | R2: LAST_UPDATE_DATE | T2: 固定 | U2: 固定 | V2: 固定 | W2: 数式 | X2: 固定 | Z2: USER_ID | AA2: USER_CODE | AB2: USER_NAME | AC2: PRF_ID | AD2: IS_LOCK | AE2: IS_DEL | AF2: CREATE_DATE | AG2: LAST_UPDATE_DATE
A3: 1 | B3: SO1 | C3: セキュリティオフィサー1 | D3: 1 | E3: N | F3: N | G3: 2018/01/01 00:00:00 | H3: 2018/01/01 00:00:00 | I3: 〇 | J3: 不可 | K3: 1 | L3: SO1 | M3: セキュリティオフィサー1 | N3: 1 | O3: N | P3: N | Q3: 2018/01/01 00:00:00 | R3: 2018/01/01 00:00:00 | T3: INSERT INTO | U3: MST_USER_TBL | V3: VALUES( | W3: =K3&" , "&"'"&L3&"'"&" , "&"'"&M3&"'"&" , "&N3&" , "&"'"&O3&"'"&" , "&"'"&P3&"'"&" , "&"to_timestamp('"&Q3&"'"&" , "&"'yyyy/MM/dd hh24:mi:ss')"&" , "&"to_timestamp('"&R3&"'"&" , "&"'yyyy/MM/dd hh24:mi:ss')" -> 1 , 'SO1' , 'セキュリティオフィサー1' , 1 , 'N' , 'N' , to_timestamp('2018/01/01 00:00:00' , 'yyyy/MM/dd hh24:mi:ss') , to_timestamp('2018/01/01 00:00:00' , 'yyyy/MM/dd hh24:mi:ss') | X3: ); | Z3: =IF(K3="","",EXACT(K3,AI3)) -> FALSE | AA3: =IF(L3="","",EXACT(L3,AJ3)) -> FALSE | AB3: =IF(M3="","",EXACT(M3,AK3)) -> FALSE | AC3: =IF(N3="","",EXACT(N3,AL3)) -> FALSE | AD3: =IF(O3="","",EXACT(O3,AM3)) -> FALSE | AE3: =IF(P3="","",EXACT(P3,AN3)) -> FALSE | AF3: =IF(Q3="","",EXACT(Q3,AO3)) -> FALSE | AG3: =IF(R3="","",EXACT(R3,AP3)) -> FALSE

Sheet 3_パスワード履歴
A1: パッケージ標準 | G1: 一覧へ | H1: ='1_プロファイルマスタ'!$H$1 -> 横浜銀行様用出荷設定 | N1: SQL
A2: PWD_HST_ID | B2: USER_ID | C2: PWD | D2: IS_INITIAL | E2: PWD_HST_DATE | F2: 構築資材 | G2: 変更可否 | H2: PWD_HST_ID | I2: USER_ID | J2: PWD | K2: IS_INITIAL | L2: PWD_HST_DATE | N2: 固定 | O2: 固定 | P2: 固定 | Q2: 数式 | R2: 固定 | T2: PWD_HST_ID | U2: USER_ID | V2: PWD | W2: IS_INITIAL | X2: PWD_HST_DATE
A3: 1 | B3: 1 | C3: 8Mrb3gxpLCN6pveJHEqxbw== | D3: Y | E3: 2018/01/01 00:00:00 | F3: 〇 | G3: 不可 | H3: 1 | I3: 1 | J3: 8Mrb3gxpLCN6pveJHEqxbw== | K3: Y | L3: 2018/01/01 00:00:00 | N3: INSERT INTO | O3: HST_PWD_TBL | P3: VALUES( | Q3: =H3&" , "&I3&" , "&"'"&J3&"'"&" , "&"'"&K3&"'"&" , "&"to_timestamp('"&L3&"'"&" , "&"'yyyy/MM/dd hh24:mi:ss')" -> 1 , 1 , '8Mrb3gxpLCN6pveJHEqxbw==' , 'Y' , to_timestamp('2018/01/01 00:00:00' , 'yyyy/MM/dd hh24:mi:ss') | R3: ); | T3: =IF(H3="","",EXACT(H3,Z3)) -> FALSE | U3: =IF(I3="","",EXACT(I3,AA3)) -> FALSE | V3: =IF(J3="","",EXACT(J3,AB3)) -> FALSE | W3: =IF(K3="","",EXACT(K3,AC3)) -> FALSE | X3: =IF(L3="","",EXACT(L3,AD3)) -> FALSE

Sheet 4_接続状態管理
A1: パッケージ標準 | G1: 一覧へ | H1: ='1_プロファイルマスタ'!$H$1 -> 横浜銀行様用出荷設定 | N1: SQL
A2: USER_ID | B2: TERM_IP | C2: LAST_LOGIN_DATE | D2: LOGIN_STAT | E2: LOGIN_FAIL_CNT | F2: 構築資材 | G2: 変更可否 | H2: USER_ID | I2: TERM_IP | J2: LAST_LOGIN_DATE | K2: LOGIN_STAT | L2: LOGIN_FAIL_CNT | N2: 固定 | O2: 固定 | P2: 固定 | Q2: 数式 | R2: 固定 | T2: USER_ID | U2: TERM_IP | V2: LAST_LOGIN_DATE | W2: LOGIN_STAT | X2: LOGIN_FAIL_CNT
A3: 1 | B3: NULL | C3: 2018/01/01 00:00:00 | D3: O | E3: 0 | F3: 〇 | G3: 不可 | H3: 1 | I3: NULL | J3: 2018/01/01 00:00:00 | K3: O | L3: 0 | N3: INSERT INTO | O3: MNG_CONN_TBL | P3: VALUES( | Q3: =H3&" , "&I3&" , "&"to_timestamp('"&J3&"'"&" , "&"'yyyy/MM/dd hh24:mi:ss')"&" , "&"'"&K3&"'"&" , "&L3 -> 1 , NULL , to_timestamp('2018/01/01 00:00:00' , 'yyyy/MM/dd hh24:mi:ss') , 'O' , 0 | R3: ); | T3: =IF(H3="","",EXACT(H3,Z3)) -> FALSE | U3: =IF(I3="","",EXACT(I3,AA3)) -> FALSE | V3: =IF(J3="","",EXACT(J3,AB3)) -> FALSE | W3: =IF(K3="","",EXACT(K3,AC3)) -> FALSE | X3: =IF(L3="","",EXACT(L3,AD3)) -> FALSE

Sheet 5_部店マスタ
A1: パッケージ標準 | G1: 一覧へ | H1: ='[1]1_プロファイルマスタ'!$H$1 -> 横浜銀行様用出荷設定 | N1: SQL
A2: UNIT_ID | B2: UNIT_CODE | C2: UNIT_NAME | D2: IS_INVALID | E2: LAST_UPDATE_DATE | F2: 構築資材 | G2: 変更可否 | H2: UNIT_ID | I2: UNIT_CODE | J2: UNIT_NAME | K2: IS_INVALID | L2: LAST_UPDATE_DATE | N2: 固定 | O2: 固定 | P2: 固定 | Q2: 数式 | R2: 固定 | T2: UNIT_ID | U2: UNIT_CODE | V2: UNIT_NAME | W2: IS_INVALID | X2: LAST_UPDATE_DATE
A3: 1 | B3: 001 | C3: 全ての部店 | D3: N | E3: 2018/01/01 00:00:00 | F3: 〇 | G3: 不可 | H3: 1 | I3: 9999 | J3: 全ての部店 | K3: N | L3: 2018/01/01 00:00:00 | N3: INSERT INTO | O3: MST_UNIT_TBL | P3: VALUES( | Q3: =H3&" , "&"'"&I3&"'"&" , "&"'"&J3&"'"&" , "&"'"&K3&"'"&" , "&"to_timestamp('"&L3&"'"&" , "&"'yyyy/MM/dd hh24:mi:ss')" -> 1 , '9999' , '全ての部店' , 'N' , to_timestamp('2018/01/01 00:00:00' , 'yyyy/MM/dd hh24:mi:ss') | R3: ); | T3: =IF(H3="","",EXACT(H3,Z3)) -> FALSE | U3: =IF(I3="","",EXACT(I3,AA3)) -> FALSE | V3: =IF(J3="","",EXACT(J3,AB3)) -> FALSE | W3: =IF(K3="","",EXACT(K3,AC3)) -> FALSE | X3: =IF(L3="","",EXACT(L3,AD3)) -> FALSE
A4: 2 | B4: 002 | C4: テスト用部店 | D4: N | E4: 2018/01/01 00:00:00 | F4: 〇 | G4: 可 | H4: 2 | I4: 0003 | J4: ＡＣＳ | K4: N | L4: 2018/01/01 00:00:00 | N4: INSERT INTO | O4: MST_UNIT_TBL | P4: VALUES( | Q4: =H4&" , "&"'"&I4&"'"&" , "&"'"&J4&"'"&" , "&"'"&K4&"'"&" , "&"to_timestamp('"&L4&"'"&" , "&"'yyyy/MM/dd hh24:mi:ss')" -> 2 , '0003' , 'ＡＣＳ' , 'N' , to_timestamp('2018/01/01 00:00:00' , 'yyyy/MM/dd hh24:mi:ss') | R4: ); | T4: =IF(H4="","",EXACT(H4,Z4)) -> FALSE | U4: =IF(I4="","",EXACT(I4,AA4)) -> FALSE | V4: =IF(J4="","",EXACT(J4,AB4)) -> FALSE | W4: =IF(K4="","",EXACT(K4,AC4)) -> FALSE | X4: =IF(L4="","",EXACT(L4,AD4)) -> FALSE
G5: 可 | H5: 3 | I5: 0005 | J5: ＣＡＦＩＳ | K5: N | L5: 2018/01/01 00:00:00 | N5: INSERT INTO | O5: MST_UNIT_TBL | P5: VALUES( | Q5: =H5&" , "&"'"&I5&"'"&" , "&"'"&J5&"'"&" , "&"'"&K5&"'"&" , "&"to_timestamp('"&L5&"'"&" , "&"'yyyy/MM/dd hh24:mi:ss')" -> 3 , '0005' , 'ＣＡＦＩＳ' , 'N' , to_timestamp('2018/01/01 00:00:00' , 'yyyy/MM/dd hh24:mi:ss') | R5: ); | T5: =IF(H5="","",EXACT(H5,Z5)) -> FALSE | U5: =IF(I5="","",EXACT(I5,AA5)) -> FALSE | V5: =IF(J5="","",EXACT(J5,AB5)) -> FALSE | W5: =IF(K5="","",EXACT(K5,AC5)) -> FALSE | X5: =IF(L5="","",EXACT(L5,AD5)) -> FALSE
G6: 可 | H6: 4 | I6: 0011 | J6: 第１研修 | K6: N | L6: 2018/01/01 00:00:00 | N6: INSERT INTO | O6: MST_UNIT_TBL | P6: VALUES( | Q6: =H6&" , "&"'"&I6&"'"&" , "&"'"&J6&"'"&" , "&"'"&K6&"'"&" , "&"to_timestamp('"&L6&"'"&" , "&"'yyyy/MM/dd hh24:mi:ss')" -> 4 , '0011' , '第１研修' , 'N' , to_timestamp('2018/01/01 00:00:00' , 'yyyy/MM/dd hh24:mi:ss') | R6: ); | T6: =IF(H6="","",EXACT(H6,Z6)) -> FALSE | U6: =IF(I6="","",EXACT(I6,AA6)) -> FALSE | V6: =IF(J6="","",EXACT(J6,AB6)) -> FALSE | W6: =IF(K6="","",EXACT(K6,AC6)) -> FALSE | X6: =IF(L6="","",EXACT(L6,AD6)) -> FALSE
G7: 可 | H7: 5 | I7: 0013 | J7: ＡＮＳＥＲ | K7: N | L7: 2018/01/01 00:00:00 | N7: INSERT INTO | O7: MST_UNIT_TBL | P7: VALUES( | Q7: =H7&" , "&"'"&I7&"'"&" , "&"'"&J7&"'"&" , "&"'"&K7&"'"&" , "&"to_timestamp('"&L7&"'"&" , "&"'yyyy/MM/dd hh24:mi:ss')" -> 5 , '0013' , 'ＡＮＳＥＲ' , 'N' , to_timestamp('2018/01/01 00:00:00' , 'yyyy/MM/dd hh24:mi:ss') | R7: ); | T7: =IF(H7="","",EXACT(H7,Z7)) -> FALSE | U7: =IF(I7="","",EXACT(I7,AA7)) -> FALSE | V7: =IF(J7="","",EXACT(J7,AB7)) -> FALSE | W7: =IF(K7="","",EXACT(K7,AC7)) -> FALSE | X7: =IF(L7="","",EXACT(L7,AD7)) -> FALSE
G8: 可 | H8: 6 | I8: 0014 | J8: 通知サービス | K8: N | L8: 2018/01/01 00:00:00 | N8: INSERT INTO | O8: MST_UNIT_TBL | P8: VALUES( | Q8: =H8&" , "&"'"&I8&"'"&" , "&"'"&J8&"'"&" , "&"'"&K8&"'"&" , "&"to_timestamp('"&L8&"'"&" , "&"'yyyy/MM/dd hh24:mi:ss')" -> 6 , '0014' , '通知サービス' , 'N' , to_timestamp('2018/01/01 00:00:00' , 'yyyy/MM/dd hh24:mi:ss') | R8: ); | T8: =IF(H8="","",EXACT(H8,Z8)) -> FALSE | U8: =IF(I8="","",EXACT(I8,AA8)) -> FALSE | V8: =IF(J8="","",EXACT(J8,AB8)) -> FALSE | W8: =IF(K8="","",EXACT(K8,AC8)) -> FALSE | X8: =IF(L8="","",EXACT(L8,AD8)) -> FALSE
G9: 可 | H9: 7 | I9: 0018 | J9: 外為系 | K9: N | L9: 2018/01/01 00:00:00 | N9: INSERT INTO | O9: MST_UNIT_TBL | P9: VALUES( | Q9: =H9&" , "&"'"&I9&"'"&" , "&"'"&J9&"'"&" , "&"'"&K9&"'"&" , "&"to_timestamp('"&L9&"'"&" , "&"'yyyy/MM/dd hh24:mi:ss')" -> 7 , '0018' , '外為系' , 'N' , to_timestamp('2018/01/01 00:00:00' , 'yyyy/MM/dd hh24:mi:ss') | R9: ); | T9: =IF(H9="","",EXACT(H9,Z9)) -> FALSE | U9: =IF(I9="","",EXACT(I9,AA9)) -> FALSE | V9: =IF(J9="","",EXACT(J9,AB9)) -> FALSE | W9: =IF(K9="","",EXACT(K9,AC9)) -> FALSE | X9: =IF(L9="","",EXACT(L9,AD9)) -> FALSE
G10: 可 | H10: 8 | I10: 0023 | J10: 自店練習店１ | K10: N | L10: 2018/01/01 00:00:00 | N10: INSERT INTO | O10: MST_UNIT_TBL | P10: VALUES( | Q10: =H10&" , "&"'"&I10&"'"&" , "&"'"&J10&"'"&" , "&"'"&K10&"'"&" , "&"to_timestamp('"&L10&"'"&" , "&"'yyyy/MM/dd hh24:mi:ss')" -> 8 , '0023' , '自店練習店１' , 'N' , to_timestamp('2018/01/01 00:00:00' , 'yyyy/MM/dd hh24:mi:ss') | R10: ); | T10: =IF(H10="","",EXACT(H10,Z10)) -> FALSE | U10: =IF(I10="","",EXACT(I10,AA10)) -> FALSE | V10: =IF(J10="","",EXACT(J10,AB10)) -> FALSE | W10: =IF(K10="","",EXACT(K10,AC10)) -> FALSE | X10: =IF(L10="","",EXACT(L10,AD10)) -> FALSE
G11: 可 | H11: 9 | I11: 0024 | J11: 自店練習店２ | K11: N | L11: 2018/01/01 00:00:00 | N11: INSERT INTO | O11: MST_UNIT_TBL | P11: VALUES( | Q11: =H11&" , "&"'"&I11&"'"&" , "&"'"&J11&"'"&" , "&"'"&K11&"'"&" , "&"to_timestamp('"&L11&"'"&" , "&"'yyyy/MM/dd hh24:mi:ss')" -> 9 , '0024' , '自店練習店２' , 'N' , to_timestamp('2018/01/01 00:00:00' , 'yyyy/MM/dd hh24:mi:ss') | R11: ); | T11: =IF(H11="","",EXACT(H11,Z11)) -> FALSE | U11: =IF(I11="","",EXACT(I11,AA11)) -> FALSE | V11: =IF(J11="","",EXACT(J11,AB11)) -> FALSE | W11: =IF(K11="","",EXACT(K11,AC11)) -> FALSE | X11: =IF(L11="","",EXACT(L11,AD11)) -> FALSE
G12: 可 | H12: 10 | I12: 0033 | J12: 第３研修 | K12: N | L12: 2018/01/01 00:00:00 | N12: INSERT INTO | O12: MST_UNIT_TBL | P12: VALUES( | Q12: =H12&" , "&"'"&I12&"'"&" , "&"'"&J12&"'"&" , "&"'"&K12&"'"&" , "&"to_timestamp('"&L12&"'"&" , "&"'yyyy/MM/dd hh24:mi:ss')" -> 10 , '0033' , '第３研修' , 'N' , to_timestamp('2018/01/01 00:00:00' , 'yyyy/MM/dd hh24:mi:ss') | R12: ); | T12: =IF(H12="","",EXACT(H12,Z12)) -> FALSE | U12: =IF(I12="","",EXACT(I12,AA12)) -> FALSE | V12: =IF(J12="","",EXACT(J12,AB12)) -> FALSE | W12: =IF(K12="","",EXACT(K12,AC12)) -> FALSE | X12: =IF(L12="","",EXACT(L12,AD12)) -> FALSE
H13: 11 | I13: 0037 | J13: 融資業務支援システム | K13: N | L13: 2018/01/01 00:00:00 | N13: INSERT INTO | O13: MST_UNIT_TBL | P13: VALUES( | Q13: =H13&" , "&"'"&I13&"'"&" , "&"'"&J13&"'"&" , "&"'"&K13&"'"&" , "&"to_timestamp('"&L13&"'"&" , "&"'yyyy/MM/dd hh24:mi:ss')" -> 11 , '0037' , '融資業務支援システム' , 'N' , to_timestamp('2018/01/01 00:00:00' , 'yyyy/MM/dd hh24:mi:ss') | R13: ); | T13: =IF(H13="","",EXACT(H13,Z13)) -> FALSE | U13: =IF(I13="","",EXACT(I13,AA13)) -> FALSE | V13: =IF(J13="","",EXACT(J13,AB13)) -> FALSE | W13: =IF(K13="","",EXACT(K13,AC13)) -> FALSE | X13: =IF(L13="","",EXACT(L13,AD13)) -> FALSE
H14: 12 | I14: 0038 | J14: 融資稟議研修店 | K14: N | L14: 2018/01/01 00:00:00 | N14: INSERT INTO | O14: MST_UNIT_TBL | P14: VALUES( | Q14: =H14&" , "&"'"&I14&"'"&" , "&"'"&J14&"'"&" , "&"'"&K14&"'"&" , "&"to_timestamp('"&L14&"'"&" , "&"'yyyy/MM/dd hh24:mi:ss')" -> 12 , '0038' , '融資稟議研修店' , 'N' , to_timestamp('2018/01/01 00:00:00' , 'yyyy/MM/dd hh24:mi:ss') | R14: ); | T14: =IF(H14="","",EXACT(H14,Z14)) -> FALSE | U14: =IF(I14="","",EXACT(I14,AA14)) -> FALSE | V14: =IF(J14="","",EXACT(J14,AB14)) -> FALSE | W14: =IF(K14="","",EXACT(K14,AC14)) -> FALSE | X14: =IF(L14="","",EXACT(L14,AD14)) -> FALSE
H15: 13 | I15: 0039 | J15: 融資稟議自店練習店 | K15: N | L15: 2018/01/01 00:00:00 | N15: INSERT INTO | O15: MST_UNIT_TBL | P15: VALUES( | Q15: =H15&" , "&"'"&I15&"'"&" , "&"'"&J15&"'"&" , "&"'"&K15&"'"&" , "&"to_timestamp('"&L15&"'"&" , "&"'yyyy/MM/dd hh24:mi:ss')" -> 13 , '0039' , '融資稟議自店練習店' , 'N' , to_timestamp('2018/01/01 00:00:00' , 'yyyy/MM/dd hh24:mi:ss') | R15: ); | T15: =IF(H15="","",EXACT(H15,Z15)) -> FALSE | U15: =IF(I15="","",EXACT(I15,AA15)) -> FALSE | V15: =IF(J15="","",EXACT(J15,AB15)) -> FALSE | W15: =IF(K15="","",EXACT(K15,AC15)) -> FALSE | X15: =IF(L15="","",EXACT(L15,AD15)) -> FALSE
H16: 14 | I16: 0041 | J16: 全銀テレ為替店１ | K16: N | L16: 2018/01/01 00:00:00 | N16: INSERT INTO | O16: MST_UNIT_TBL | P16: VALUES( | Q16: =H16&" , "&"'"&I16&"'"&" , "&"'"&J16&"'"&" , "&"'"&K16&"'"&" , "&"to_timestamp('"&L16&"'"&" , "&"'yyyy/MM/dd hh24:mi:ss')" -> 14 , '0041' , '全銀テレ為替店１' , 'N' , to_timestamp('2018/01/01 00:00:00' , 'yyyy/MM/dd hh24:mi:ss') | R16: ); | T16: =IF(H16="","",EXACT(H16,Z16)) -> FALSE | U16: =IF(I16="","",EXACT(I16,AA16)) -> FALSE | V16: =IF(J16="","",EXACT(J16,AB16)) -> FALSE | W16: =IF(K16="","",EXACT(K16,AC16)) -> FALSE | X16: =IF(L16="","",EXACT(L16,AD16)) -> FALSE
H17: 15 | I17: 0042 | J17: 全銀テレ為替店２ | K17: N | L17: 2018/01/01 00:00:00 | N17: INSERT INTO | O17: MST_UNIT_TBL | P17: VALUES( | Q17: =H17&" , "&"'"&I17&"'"&" , "&"'"&J17&"'"&" , "&"'"&K17&"'"&" , "&"to_timestamp('"&L17&"'"&" , "&"'yyyy/MM/dd hh24:mi:ss')" -> 15 , '0042' , '全銀テレ為替店２' , 'N' , to_timestamp('2018/01/01 00:00:00' , 'yyyy/MM/dd hh24:mi:ss') | R17: ); | T17: =IF(H17="","",EXACT(H17,Z17)) -> FALSE | U17: =IF(I17="","",EXACT(I17,AA17)) -> FALSE | V17: =IF(J17="","",EXACT(J17,AB17)) -> FALSE | W17: =IF(K17="","",EXACT(K17,AC17)) -> FALSE | X17: =IF(L17="","",EXACT(L17,AD17)) -> FALSE
H18: 16 | I18: 0043 | J18: 全銀ＭＴ伝送店１ | K18: N | L18: 2018/01/01 00:00:00 | N18: INSERT INTO | O18: MST_UNIT_TBL | P18: VALUES( | Q18: =H18&" , "&"'"&I18&"'"&" , "&"'"&J18&"'"&" , "&"'"&K18&"'"&" , "&"to_timestamp('"&L18&"'"&" , "&"'yyyy/MM/dd hh24:mi:ss')" -> 16 , '0043' , '全銀ＭＴ伝送店１' , 'N' , to_timestamp('2018/01/01 00:00:00' , 'yyyy/MM/dd hh24:mi:ss') | R18: ); | T18: =IF(H18="","",EXACT(H18,Z18)) -> FALSE | U18: =IF(I18="","",EXACT(I18,AA18)) -> FALSE | V18: =IF(J18="","",EXACT(J18,AB18)) -> FALSE | W18: =IF(K18="","",EXACT(K18,AC18)) -> FALSE | X18: =IF(L18="","",EXACT(L18,AD18)) -> FALSE
H19: 17 | I19: 0044 | J19: 全銀ＭＴ伝送店２ | K19: N | L19: 2018/01/01 00:00:00 | N19: INSERT INTO | O19: MST_UNIT_TBL | P19: VALUES( | Q19: =H19&" , "&"'"&I19&"'"&" , "&"'"&J19&"'"&" , "&"'"&K19&"'"&" , "&"to_timestamp('"&L19&"'"&" , "&"'yyyy/MM/dd hh24:mi:ss')" -> 17 , '0044' , '全銀ＭＴ伝送店２' , 'N' , to_timestamp('2018/01/01 00:00:00' , 'yyyy/MM/dd hh24:mi:ss') | R19: ); | T19: =IF(H19="","",EXACT(H19,Z19)) -> FALSE | U19: =IF(I19="","",EXACT(I19,AA19)) -> FALSE | V19: =IF(J19="","",EXACT(J19,AB19)) -> FALSE | W19: =IF(K19="","",EXACT(K19,AC19)) -> FALSE | X19: =IF(L19="","",EXACT(L19,AD19)) -> FALSE
H20: 18 | I20: 0045 | J20: ＡＴＭ宝くじ | K20: N | L20: 2018/01/01 00:00:00 | N20: INSERT INTO | O20: MST_UNIT_TBL | P20: VALUES( | Q20: =H20&" , "&"'"&I20&"'"&" , "&"'"&J20&"'"&" , "&"'"&K20&"'"&" , "&"to_timestamp('"&L20&"'"&" , "&"'yyyy/MM/dd hh24:mi:ss')" -> 18 , '0045' , 'ＡＴＭ宝くじ' , 'N' , to_timestamp('2018/01/01 00:00:00' , 'yyyy/MM/dd hh24:mi:ss') | R20: ); | T20: =IF(H20="","",EXACT(H20,Z20)) -> FALSE | U20: =IF(I20="","",EXACT(I20,AA20)) -> FALSE | V20: =IF(J20="","",EXACT(J20,AB20)) -> FALSE | W20: =IF(K20="","",EXACT(K20,AC20)) -> FALSE | X20: =IF(L20="","",EXACT(L20,AD20)) -> FALSE
H21: 19 | I21: 0061 | J21: オペレーションセンター | K21: N | L21: 2018/01/01 00:00:00 | N21: INSERT INTO | O21: MST_UNIT_TBL | P21: VALUES( | Q21: =H21&" , "&"'"&I21&"'"&" , "&"'"&J21&"'"&" , "&"'"&K21&"'"&" , "&"to_timestamp('"&L21&"'"&" , "&"'yyyy/MM/dd hh24:mi:ss')" -> 19 , '0061' , 'オペレーションセンター' , 'N' , to_timestamp('2018/01/01 00:00:00' , 'yyyy/MM/dd hh24:mi:ss') | R21: ); | T21: =IF(H21="","",EXACT(H21,Z21)) -> FALSE | U21: =IF(I21="","",EXACT(I21,AA21)) -> FALSE | V21: =IF(J21="","",EXACT(J21,AB21)) -> FALSE | W21: =IF(K21="","",EXACT(K21,AC21)) -> FALSE | X21: =IF(L21="","",EXACT(L21,AD21)) -> FALSE
H22: 20 | I22: 0062 | J22: ＯＣＲ集中店 | K22: N | L22: 2018/01/01 00:00:00 | N22: INSERT INTO | O22: MST_UNIT_TBL | P22: VALUES( | Q22: =H22&" , "&"'"&I22&"'"&" , "&"'"&J22&"'"&" , "&"'"&K22&"'"&" , "&"to_timestamp('"&L22&"'"&" , "&"'yyyy/MM/dd hh24:mi:ss')" -> 20 , '0062' , 'ＯＣＲ集中店' , 'N' , to_timestamp('2018/01/01 00:00:00' , 'yyyy/MM/dd hh24:mi:ss') | R22: ); | T22: =IF(H22="","",EXACT(H22,Z22)) -> FALSE | U22: =IF(I22="","",EXACT(I22,AA22)) -> FALSE | V22: =IF(J22="","",EXACT(J22,AB22)) -> FALSE | W22: =IF(K22="","",EXACT(K22,AC22)) -> FALSE | X22: =IF(L22="","",EXACT(L22,AD22)) -> FALSE
H23: 21 | I23: 0070 | J23: 金沢住宅ローンセンター | K23: N | L23: 2018/01/01 00:00:00 | N23: INSERT INTO | O23: MST_UNIT_TBL | P23: VALUES( | Q23: =H23&" , "&"'"&I23&"'"&" , "&"'"&J23&"'"&" , "&"'"&K23&"'"&" , "&"to_timestamp('"&L23&"'"&" , "&"'yyyy/MM/dd hh24:mi:ss')" -> 21 , '0070' , '金沢住宅ローンセンター' , 'N' , to_timestamp('2018/01/01 00:00:00' , 'yyyy/MM/dd hh24:mi:ss') | R23: ); | T23: =IF(H23="","",EXACT(H23,Z23)) -> FALSE | U23: =IF(I23="","",EXACT(I23,AA23)) -> FALSE | V23: =IF(J23="","",EXACT(J23,AB23)) -> FALSE | W23: =IF(K23="","",EXACT(K23,AC23)) -> FALSE | X23: =IF(L23="","",EXACT(L23,AD23)) -> FALSE
H24: 22 | I24: 0071 | J24: 中山住宅ローンセンター | K24: N | L24: 2018/01/01 00:00:00 | N24: INSERT INTO | O24: MST_UNIT_TBL | P24: VALUES( | Q24: =H24&" , "&"'"&I24&"'"&" , "&"'"&J24&"'"&" , "&"'"&K24&"'"&" , "&"to_timestamp('"&L24&"'"&" , "&"'yyyy/MM/dd hh24:mi:ss')" -> 22 , '0071' , '中山住宅ローンセンター' , 'N' , to_timestamp('2018/01/01 00:00:00' , 'yyyy/MM/dd hh24:mi:ss') | R24: ); | T24: =IF(H24="","",EXACT(H24,Z24)) -> FALSE | U24: =IF(I24="","",EXACT(I24,AA24)) -> FALSE | V24: =IF(J24="","",EXACT(J24,AB24)) -> FALSE | W24: =IF(K24="","",EXACT(K24,AC24)) -> FALSE | X24: =IF(L24="","",EXACT(L24,AD24)) -> FALSE
... H272: 270 | I272: 0971 | J272: 大阪支店 | K272: N | L272: 2018/01/01 00:00:00 | N272: INSERT INTO | O272: MST_UNIT_TBL | P272: VALUES( | Q272: =H272&" , "&"'"&I272&"'"&" , "&"'"&J272&"'"&" , "&"'"&K272&"'"&" , "&"to_timestamp('"&L272&"'"&" , "&"'yyyy/MM/dd hh24:mi:ss')" -> 270 , '0971' , '大阪支店' , 'N' , to_timestamp('2018/01/01 00:00:00' , 'yyyy/MM/dd hh24:mi:ss') | R272: ); | T272: =IF(H272="","",EXACT(H272,Z272)) -> FALSE | U272: =IF(I272="","",EXACT(I272,AA272)) -> FALSE | V272: =IF(J272="","",EXACT(J272,AB272)) -> FALSE | W272: =IF(K272="","",EXACT(K272,AC272)) -> FALSE | X272: =IF(L272="","",EXACT(L272,AD272)) -> FALSE
H273: 271 | I273: 10000 | J273: 横浜銀行 | K273: N | L273: 2018/01/01 00:00:00 | N273: INSERT INTO | O273: MST_UNIT_TBL | P273: VALUES( | Q273: =H273&" , "&"'"&I273&"'"&" , "&"'"&J273&"'"&" , "&"'"&K273&"'"&" , "&"to_timestamp('"&L273&"'"&" , "&"'yyyy/MM/dd hh24:mi:ss')" -> 271 , '10000' , '横浜銀行' , 'N' , to_timestamp('2018/01/01 00:00:00' , 'yyyy/MM/dd hh24:mi:ss') | R273: ); | T273: =IF(H273="","",EXACT(H273,Z273)) -> FALSE | U273: =IF(I273="","",EXACT(I273,AA273)) -> FALSE | V273: =IF(J273="","",EXACT(J273,AB273)) -> FALSE | W273: =IF(K273="","",EXACT(K273,AC273)) -> FALSE | X273: =IF(L273="","",EXACT(L273,AD273)) -> FALSE
H274: 273 | I274: 10001 | J274: 本部 | K274: N | L274: 2018/01/01 00:00:00 | N274: INSERT INTO | O274: MST_UNIT_TBL | P274: VALUES( | Q274: =H274&" , "&"'"&I274&"'"&" , "&"'"&J274&"'"&" , "&"'"&K274&"'"&" , "&"to_timestamp('"&L274&"'"&" , "&"'yyyy/MM/dd hh24:mi:ss')" -> 273 , '10001' , '本部' , 'N' , to_timestamp('2018/01/01 00:00:00' , 'yyyy/MM/dd hh24:mi:ss') | R274: ); | T274: =IF(H274="","",EXACT(H274,Z274)) -> FALSE | U274: =IF(I274="","",EXACT(I274,AA274)) -> FALSE | V274: =IF(J274="","",EXACT(J274,AB274)) -> FALSE | W274: =IF(K274="","",EXACT(K274,AC274)) -> FALSE | X274: =IF(L274="","",EXACT(L274,AD274)) -> FALSE
H275: 274 | I275: 10002 | J275: 地域地区本部 | K275: N | L275: 2018/01/01 00:00:00 | N275: INSERT INTO | O275: MST_UNIT_TBL | P275: VALUES( | Q275: =H275&" , "&"'"&I275&"'"&" , "&"'"&J275&"'"&" , "&"'"&K275&"'"&" , "&"to_timestamp('"&L275&"'"&" , "&"'yyyy/MM/dd hh24:mi:ss')" -> 274 , '10002' , '地域地区本部' , 'N' , to_timestamp('2018/01/01 00:00:00' , 'yyyy/MM/dd hh24:mi:ss') | R275: ); | T275: =IF(H275="","",EXACT(H275,Z275)) -> FALSE | U275: =IF(I275="","",EXACT(I275,AA275)) -> FALSE | V275: =IF(J275="","",EXACT(J275,AB275)) -> FALSE | W275: =IF(K275="","",EXACT(K275,AC275)) -> FALSE | X275: =IF(L275="","",EXACT(L275,AD275)) -> FALSE
H276: 275 | I276: 10003 | J276: 営業店 | K276: N | L276: 2018/01/01 00:00:00 | N276: INSERT INTO | O276: MST_UNIT_TBL | P276: VALUES( | Q276: =H276&" , "&"'"&I276&"'"&" , "&"'"&J276&"'"&" , "&"'"&K276&"'"&" , "&"to_timestamp('"&L276&"'"&" , "&"'yyyy/MM/dd hh24:mi:ss')" -> 275 , '10003' , '営業店' , 'N' , to_timestamp('2018/01/01 00:00:00' , 'yyyy/MM/dd hh24:mi:ss') | R276: ); | T276: =IF(H276="","",EXACT(H276,Z276)) -> FALSE | U276: =IF(I276="","",EXACT(I276,AA276)) -> FALSE | V276: =IF(J276="","",EXACT(J276,AB276)) -> FALSE | W276: =IF(K276="","",EXACT(K276,AC276)) -> FALSE | X276: =IF(L276="","",EXACT(L276,AD276)) -> FALSE
H277: 276 | I277: 10004 | J277: 海外拠点 | K277: N | L277: 2018/01/01 00:00:00 | N277: INSERT INTO | O277: MST_UNIT_TBL | P277: VALUES( | Q277: =H277&" , "&"'"&I277&"'"&" , "&"'"&J277&"'"&" , "&"'"&K277&"'"&" , "&"to_timestamp('"&L277&"'"&" , "&"'yyyy/MM/dd hh24:mi:ss')" -> 276 , '10004' , '海外拠点' , 'N' , to_timestamp('2018/01/01 00:00:00' , 'yyyy/MM/dd hh24:mi:ss') | R277: ); | T277: =IF(H277="","",EXACT(H277,Z277)) -> FALSE | U277: =IF(I277="","",EXACT(I277,AA277)) -> FALSE | V277: =IF(J277="","",EXACT(J277,AB277)) -> FALSE | W277: =IF(K277="","",EXACT(K277,AC277)) -> FALSE | X277: =IF(L277="","",EXACT(L277,AD277)) -> FALSE
H278: 277 | I278: 10005 | J278: 横浜銀行関連会社 | K278: N | L278: 2018/01/01 00:00:00 | N278: INSERT INTO | O278: MST_UNIT_TBL | P278: VALUES( | Q278: =H278&" , "&"'"&I278&"'"&" , "&"'"&J278&"'"&" , "&"'"&K278&"'"&" , "&"to_timestamp('"&L278&"'"&" , "&"'yyyy/MM/dd hh24:mi:ss')" -> 277 , '10005' , '横浜銀行関連会社' , 'N' , to_timestamp('2018/01/01 00:00:00' , 'yyyy/MM/dd hh24:mi:ss') | R278: ); | T278: =IF(H278="","",EXACT(H278,Z278)) -> FALSE | U278: =IF(I278="","",EXACT(I278,AA278)) -> FALSE | V278: =IF(J278="","",EXACT(J278,AB278)) -> FALSE | W278: =IF(K278="","",EXACT(K278,AC278)) -> FALSE | X278: =IF(L278="","",EXACT(L278,AD278)) -> FALSE
H279: 278 | I279: 12000 | J279: 総合企画部 | K279: N | L279: 2018/01/01 00:00:00 | N279: INSERT INTO | O279: MST_UNIT_TBL | P279: VALUES( | Q279: =H279&" , "&"'"&I279&"'"&" , "&"'"&J279&"'"&" , "&"'"&K279&"'"&" , "&"to_timestamp('"&L279&"'"&" , "&"'yyyy/MM/dd hh24:mi:ss')" -> 278 , '12000' , '総合企画部' , 'N' , to_timestamp('2018/01/01 00:00:00' , 'yyyy/MM/dd hh24:mi:ss') | R279: ); | T279: =IF(H279="","",EXACT(H279,Z279)) -> FALSE | U279: =IF(I279="","",EXACT(I279,AA279)) -> FALSE | V279: =IF(J279="","",EXACT(J279,AB279)) -> FALSE | W279: =IF(K279="","",EXACT(K279,AC279)) -> FALSE | X279: =IF(L279="","",EXACT(L279,AD279)) -> FALSE
H280: 279 | I280: 12001 | J280: 総合企画部協会担当 | K280: N | L280: 2018/01/01 00:00:00 | N280: INSERT INTO | O280: MST_UNIT_TBL | P280: VALUES( | Q280: =H280&" , "&"'"&I280&"'"&" , "&"'"&J280&"'"&" , "&"'"&K280&"'"&" , "&"to_timestamp('"&L280&"'"&" , "&"'yyyy/MM/dd hh24:mi:ss')" -> 279 , '12001' , '総合企画部協会担当' , 'N' , to_timestamp('2018/01/01 00:00:00' , 'yyyy/MM/dd hh24:mi:ss') | R280: ); | T280: =IF(H280="","",EXACT(H280,Z280)) -> FALSE | U280: =IF(I280="","",EXACT(I280,AA280)) -> FALSE | V280: =IF(J280="","",EXACT(J280,AB280)) -> FALSE | W280: =IF(K280="","",EXACT(K280,AC280)) -> FALSE | X280: =IF(L280="","",EXACT(L280,AD280)) -> FALSE
H281: 280 | I281: 12003 | J281: 総合企画部コーポレートコミュニケーション推進室 | K281: N | L281: 2018/01/01 00:00:00 | N281: INSERT INTO | O281: MST_UNIT_TBL | P281: VALUES( | Q281: =H281&" , "&"'"&I281&"'"&" , "&"'"&J281&"'"&" , "&"'"&K281&"'"&" , "&"to_timestamp('"&L281&"'"&" , "&"'yyyy/MM/dd hh24:mi:ss')" -> 280 , '12003' , '総合企画部コーポレートコミュニケーション推進室' , 'N' , to_timestamp('2018/01/01 00:00:00' , 'yyyy/MM/dd hh24:mi:ss') | R281: ); | T281: =IF(H281="","",EXACT(H281,Z281)) -> FALSE | U281: =IF(I281="","",EXACT(I281,AA281)) -> FALSE | V281: =IF(J281="","",EXACT(J281,AB281)) -> FALSE | W281: =IF(K281="","",EXACT(K281,AC281)) -> FALSE | X281: =IF(L281="","",EXACT(L281,AD281)) -> FALSE
H282: 281 | I282: 12004 | J282: 総合企画部主計室 | K282: N | L282: 2018/01/01 00:00:00 | N282: INSERT INTO | O282: MST_UNIT_TBL | P282: VALUES( | Q282: =H282&" , "&"'"&I282&"'"&" , "&"'"&J282&"'"&" , "&"'"&K282&"'"&" , "&"to_timestamp('"&L282&"'"&" , "&"'yyyy/MM/dd hh24:mi:ss')" -> 281 , '12004' , '総合企画部主計室' , 'N' , to_timestamp('2018/01/01 00:00:00' , 'yyyy/MM/dd hh24:mi:ss') | R282: ); | T282: =IF(H282="","",EXACT(H282,Z282)) -> FALSE | U282: =IF(I282="","",EXACT(I282,AA282)) -> FALSE | V282: =IF(J282="","",EXACT(J282,AB282)) -> FALSE | W282: =IF(K282="","",EXACT(K282,AC282)) -> FALSE | X282: =IF(L282="","",EXACT(L282,AD282)) -> FALSE
H283: 282 | I283: 12005 | J283: 総合企画部関連事業室 | K283: N | L283: 2018/01/01 00:00:00 | N283: INSERT INTO | O283: MST_UNIT_TBL | P283: VALUES( | Q283: =H283&" , "&"'"&I283&"'"&" , "&"'"&J283&"'"&" , "&"'"&K283&"'"&" , "&"to_timestamp('"&L283&"'"&" , "&"'yyyy/MM/dd hh24:mi:ss')" -> 282 , '12005' , '総合企画部関連事業室' , 'N' , to_timestamp('2018/01/01 00:00:00' , 'yyyy/MM/dd hh24:mi:ss') | R283: ); | T283: =IF(H283="","",EXACT(H283,Z283)) -> FALSE | U283: =IF(I283="","",EXACT(I283,AA283)) -> FALSE | V283: =IF(J283="","",EXACT(J283,AB283)) -> FALSE | W283: =IF(K283="","",EXACT(K283,AC283)) -> FALSE | X283: =IF(L283="","",EXACT(L283,AD283)) -> FALSE
H284: 283 | I284: 12006 | J284: 総合企画部秘書室 | K284: N | L284: 2018/01/01 00:00:00 | N284: INSERT INTO | O284: MST_UNIT_TBL | P284: VALUES( | Q284: =H284&" , "&"'"&I284&"'"&" , "&"'"&J284&"'"&" , "&"'"&K284&"'"&" , "&"to_timestamp('"&L284&"'"&" , "&"'yyyy/MM/dd hh24:mi:ss')" -> 283 , '12006' , '総合企画部秘書室' , 'N' , to_timestamp('2018/01/01 00:00:00' , 'yyyy/MM/dd hh24:mi:ss') | R284: ); | T284: =IF(H284="","",EXACT(H284,Z284)) -> FALSE | U284: =IF(I284="","",EXACT(I284,AA284)) -> FALSE | V284: =IF(J284="","",EXACT(J284,AB284)) -> FALSE | W284: =IF(K284="","",EXACT(K284,AC284)) -> FALSE | X284: =IF(L284="","",EXACT(L284,AD284)) -> FALSE
... H550: 554 | I550: 99962 | J550: 横浜ＦＧ | K550: N | L550: 2026/04/07 00:00:00 | N550: INSERT INTO | O550: MST_UNIT_TBL | P550: VALUES( | Q550: =H550&" , "&"'"&I550&"'"&" , "&"'"&J550&"'"&" , "&"'"&K550&"'"&" , "&"to_timestamp('"&L550&"'"&" , "&"'yyyy/MM/dd hh24:mi:ss')" -> 554 , '99962' , '横浜ＦＧ' , 'N' , to_timestamp('2026/04/07 00:00:00' , 'yyyy/MM/dd hh24:mi:ss') | R550: ); | T550: =IF(H550="","",EXACT(H550,Z550)) -> FALSE | U550: =IF(I550="","",EXACT(I550,AA550)) -> FALSE | V550: =IF(J550="","",EXACT(J550,AB550)) -> FALSE | W550: =IF(K550="","",EXACT(K550,AC550)) -> FALSE | X550: =IF(L550="","",EXACT(L550,AD550)) -> FALSE
H551: 555 | I551: testA | J551: 試行用本店営業部 | K551: N | L551: 2018/01/01 00:00:00 | N551: INSERT INTO | O551: MST_UNIT_TBL | P551: VALUES( | Q551: =H551&" , "&"'"&I551&"'"&" , "&"'"&J551&"'"&" , "&"'"&K551&"'"&" , "&"to_timestamp('"&L551&"'"&" , "&"'yyyy/MM/dd hh24:mi:ss')" -> 555 , 'testA' , '試行用本店営業部' , 'N' , to_timestamp('2018/01/01 00:00:00' , 'yyyy/MM/dd hh24:mi:ss') | R551: ); | T551: =IF(H551="","",EXACT(H551,Z551)) -> FALSE | U551: =IF(I551="","",EXACT(I551,AA551)) -> FALSE | V551: =IF(J551="","",EXACT(J551,AB551)) -> FALSE | W551: =IF(K551="","",EXACT(K551,AC551)) -> FALSE | X551: =IF(L551="","",EXACT(L551,AD551)) -> FALSE
H552: 556 | I552: testB | J552: 試行用新横浜支店 | K552: N | L552: 2018/01/01 00:00:00 | N552: INSERT INTO | O552: MST_UNIT_TBL | P552: VALUES( | Q552: =H552&" , "&"'"&I552&"'"&" , "&"'"&J552&"'"&" , "&"'"&K552&"'"&" , "&"to_timestamp('"&L552&"'"&" , "&"'yyyy/MM/dd hh24:mi:ss')" -> 556 , 'testB' , '試行用新横浜支店' , 'N' , to_timestamp('2018/01/01 00:00:00' , 'yyyy/MM/dd hh24:mi:ss') | R552: ); | T552: =IF(H552="","",EXACT(H552,Z552)) -> FALSE | U552: =IF(I552="","",EXACT(I552,AA552)) -> FALSE | V552: =IF(J552="","",EXACT(J552,AB552)) -> FALSE | W552: =IF(K552="","",EXACT(K552,AC552)) -> FALSE | X552: =IF(L552="","",EXACT(L552,AD552)) -> FALSE
...

Sheet 6_ユーザ部店設定
A1: パッケージ標準 | E1: 一覧へ | F1: ='1_プロファイルマスタ'!$H$1 -> 横浜銀行様用出荷設定 | J1: SQL
A2: UNIT_ID | B2: USER_ID | C2: IS_DEFAULT | D2: 構築資材 | E2: 変更可否 | F2: UNIT_ID | G2: USER_ID | H2: IS_DEFAULT | J2: 固定 | K2: 固定 | L2: 固定 | M2: 数式 | N2: 固定 | P2: UNIT_ID | Q2: USER_ID | R2: IS_DEFAULT
A3: 1 | B3: 1 | C3: N | D3: 〇 | E3: 不可 | F3: 1 | G3: 1 | H3: N | J3: INSERT INTO | K3: CNF_UNIT_TBL | L3: VALUES( | M3: =F3&" , "&G3&" , "&"'"&H3&"'" -> 1 , 1 , 'N' | N3: ); | P3: =IF(F3="","",EXACT(F3,T3)) -> FALSE | Q3: =IF(G3="","",EXACT(G3,U3)) -> FALSE | R3: =IF(H3="","",EXACT(H3,V3)) -> FALSE

Sheet 7_取引分類マスタ
A1: パッケージ標準 | D1: 一覧へ | E1: ='1_プロファイルマスタ'!$H$1 -> 横浜銀行様用出荷設定 | H1: SQL
A2: DEAL_TYPE_ID | B2: DEAL_TYPE | C2: 構築資材 | D2: 変更可否 | E2: DEAL_TYPE_ID | F2: DEAL_TYPE | G2: 備考 | H2: 固定 | I2: 固定 | J2: 固定 | K2: 数式 | L2: 固定 | N2: DEAL_TYPE_ID | O2: DEAL_TYPE
A3: 1 | B3: 共通 | C3: 〇 | D3: 不可 | E3: 1 | F3: 共通 | H3: INSERT INTO | I3: MST_DEAL_TYPE_TBL | J3: VALUES( | K3: =E3&" , "&"'"&F3&"'" -> 1 , '共通' | L3: ); | N3: =IF(E3="","",EXACT(E3,Q3)) -> FALSE | O3: =IF(F3="","",EXACT(F3,R3)) -> FALSE
A4: 2 | B4: 管理 | C4: 〇 | D4: 不可 | E4: 2 | F4: 管理 | H4: INSERT INTO | I4: MST_DEAL_TYPE_TBL | J4: VALUES( | K4: =E4&" , "&"'"&F4&"'" -> 2 , '管理' | L4: ); | N4: =IF(E4="","",EXACT(E4,Q4)) -> FALSE | O4: =IF(F4="","",EXACT(F4,R4)) -> FALSE
A5: 3 | B5: 本人確認 | C5: 〇 | D5: 不可 | E5: 3 | F5: 本人確認 | H5: INSERT INTO | I5: MST_DEAL_TYPE_TBL | J5: VALUES( | K5: =E5&" , "&"'"&F5&"'" -> 3 , '本人確認' | L5: ); | N5: =IF(E5="","",EXACT(E5,Q5)) -> FALSE | O5: =IF(F5="","",EXACT(F5,R5)) -> FALSE
A6: 4 | B6: バッチフィルタリング | C6: 〇 | D6: 不可 | E6: 4 | F6: バッチフィルタリング | H6: INSERT INTO | I6: MST_DEAL_TYPE_TBL | J6: VALUES( | K6: =E6&" , "&"'"&F6&"'" -> 4 , 'バッチフィルタリング' | L6: ); | N6: =IF(E6="","",EXACT(E6,Q6)) -> FALSE | O6: =IF(F6="","",EXACT(F6,R6)) -> FALSE
A7: 5 | B7: リアルフィルタリング | C7: 〇 | D7: 不可 | E7: 5 | F7: リアルフィルタリング | H7: INSERT INTO | I7: MST_DEAL_TYPE_TBL | J7: VALUES( | K7: =E7&" , "&"'"&F7&"'" -> 5 , 'リアルフィルタリング' | L7: ); | N7: =IF(E7="","",EXACT(E7,Q7)) -> FALSE | O7: =IF(F7="","",EXACT(F7,R7)) -> FALSE
A8: 6 | B8: シミュレーション | C8: 〇 | D8: 不可 | E8: 6 | F8: シミュレーション | H8: INSERT INTO | I8: MST_DEAL_TYPE_TBL | J8: VALUES( | K8: =E8&" , "&"'"&F8&"'" -> 6 , 'シミュレーション' | L8: ); | N8: =IF(E8="","",EXACT(E8,Q8)) -> FALSE | O8: =IF(F8="","",EXACT(F8,R8)) -> FALSE
A9: 7 | B9: リスト管理 | C9: 〇 | D9: 不可 | E9: 7 | F9: リスト管理 | H9: INSERT INTO | I9: MST_DEAL_TYPE_TBL | J9: VALUES( | K9: =E9&" , "&"'"&F9&"'" -> 7 , 'リスト管理' | L9: ); | N9: =IF(E9="","",EXACT(E9,Q9)) -> FALSE | O9: =IF(F9="","",EXACT(F9,R9)) -> FALSE
A10: 8 | B10: 長期保管DB参照 | C10: × | D10: 不可 | G10: PKGでは不要 | H10: INSERT INTO | I10: MST_DEAL_TYPE_TBL | J10: VALUES( | K10: =E10&" , "&"'"&F10&"'" -> , '' | L10: ); | N10: =IF(E10="","",EXACT(E10,Q10)) | O10: =IF(F10="","",EXACT(F10,R10))
A11: 9 | B11: オンライン反映 | C11: × | D11: 不可 | G11: PKGでは不要 | H11: INSERT INTO | I11: MST_DEAL_TYPE_TBL | J11: VALUES( | K11: =E11&" , "&"'"&F11&"'" -> , '' | L11: ); | N11: =IF(E11="","",EXACT(E11,Q11)) | O11: =IF(F11="","",EXACT(F11,R11))

Sheet 8_取引マスタ
A1: パッケージ標準 | I1: 一覧へ | J1: ='1_プロファイルマスタ'!$H$1 -> 横浜銀行様用出荷設定 | R1: SQL
A2: DEAL_ID | B2: DEAL_NAME | C2: DEAL_TYPE_ID | D2: DEAL_NO | E2: ACTION_PATH | F2: UPTIME_FROM | G2: UPTIME_TO | H2: 構築資材 | I2: 変更可否 | J2: DEAL_ID | K2: DEAL_NAME | L2: DEAL_TYPE_ID | M2: DEAL_NO | N2: ACTION_PATH | O2: UPTIME_FROM | P2: UPTIME_TO | Q2: 備考 | R2: 固定 | S2: 固定 | T2: 固定 | U2: 数式 | V2: 固定 | X2: DEAL_ID | Y2: DEAL_NAME | Z2: DEAL_TYPE_ID | AA2: DEAL_NO | AB2: ACTION_PATH | AC2: UPTIME_FROM | AD2: UPTIME_TO
A3: 1 | B3: ログイン | C3: 1 | D3: 1 | E3: NULL | F3: NULL | G3: NULL | H3: 〇 | I3: 不可 | J3: 1 | K3: ログイン | L3: 1 | M3: 1 | N3: NULL | O3: NULL | P3: NULL | R3: INSERT INTO | S3: MST_DEAL_TBL | T3: VALUES( | U3: =J3&" , "&"'"&K3&"'"&" , "&L3&" , "&M3&" , "&N3&" , "&O3&" , "&P3 -> 1 , 'ログイン' , 1 , 1 , NULL , NULL , NULL | V3: ); | X3: =IF(J3="","",EXACT(J3,AF3)) -> FALSE | Y3: =IF(K3="","",EXACT(K3,AG3)) -> FALSE | Z3: =IF(L3="","",EXACT(L3,AH3)) -> FALSE | AA3: =IF(M3="","",EXACT(M3,AI3)) -> FALSE | AB3: =IF(N3="","",EXACT(N3,AJ3)) -> FALSE | AC3: =IF(O3="","",EXACT(O3,AK3)) -> FALSE | AD3: =IF(P3="","",EXACT(P3,AL3)) -> FALSE
A4: 2 | B4: メニュー | C4: 1 | D4: 1 | E4: NULL | F4: NULL | G4: NULL | H4: 〇 | I4: 不可 | J4: 2 | K4: メニュー | L4: 1 | M4: 1 | N4: NULL | O4: NULL | P4: NULL | R4: INSERT INTO | S4: MST_DEAL_TBL | T4: VALUES( | U4: =J4&" , "&"'"&K4&"'"&" , "&L4&" , "&M4&" , "&N4&" , "&O4&" , "&P4 -> 2 , 'メニュー' , 1 , 1 , NULL , NULL , NULL | V4: ); | X4: =IF(J4="","",EXACT(J4,AF4)) -> FALSE | Y4: =IF(K4="","",EXACT(K4,AG4)) -> FALSE | Z4: =IF(L4="","",EXACT(L4,AH4)) -> FALSE | AA4: =IF(M4="","",EXACT(M4,AI4)) -> FALSE | AB4: =IF(N4="","",EXACT(N4,AJ4)) -> FALSE | AC4: =IF(O4="","",EXACT(O4,AK4)) -> FALSE | AD4: =IF(P4="","",EXACT(P4,AL4)) -> FALSE
A5: 3 | B5: ヘッダー | C5: 1 | D5: 1 | E5: NULL | F5: NULL | G5: NULL | H5: 〇 | I5: 不可 | J5: 3 | K5: ヘッダー | L5: 1 | M5: 1 | N5: NULL | O5: NULL | P5: NULL | R5: INSERT INTO | S5: MST_DEAL_TBL | T5: VALUES( | U5: =J5&" , "&"'"&K5&"'"&" , "&L5&" , "&M5&" , "&N5&" , "&O5&" , "&P5 -> 3 , 'ヘッダー' , 1 , 1 , NULL , NULL , NULL | V5: ); | X5: =IF(J5="","",EXACT(J5,AF5)) -> FALSE | Y5: =IF(K5="","",EXACT(K5,AG5)) -> FALSE | Z5: =IF(L5="","",EXACT(L5,AH5)) -> FALSE | AA5: =IF(M5="","",EXACT(M5,AI5)) -> FALSE | AB5: =IF(N5="","",EXACT(N5,AJ5)) -> FALSE | AC5: =IF(O5="","",EXACT(O5,AK5)) -> FALSE | AD5: =IF(P5="","",EXACT(P5,AL5)) -> FALSE
A6: 4 | B6: パスワード変更 | C6: 2 | D6: 1 | E6: NULL | F6: NULL | G6: NULL | H6: 〇 | I6: 不可 | J6: 4 | K6: パスワード変更 | L6: 2 | M6: 1 | N6: NULL | O6: NULL | P6: NULL | R6: INSERT INTO | S6: MST_DEAL_TBL | T6: VALUES( | U6: =J6&" , "&"'"&K6&"'"&" , "&L6&" , "&M6&" , "&N6&" , "&O6&" , "&P6 -> 4 , 'パスワード変更' , 2 , 1 , NULL , NULL , NULL | V6: ); | X6: =IF(J6="","",EXACT(J6,AF6)) -> FALSE | Y6: =IF(K6="","",EXACT(K6,AG6)) -> FALSE | Z6: =IF(L6="","",EXACT(L6,AH6)) -> FALSE | AA6: =IF(M6="","",EXACT(M6,AI6)) -> FALSE | AB6: =IF(N6="","",EXACT(N6,AJ6)) -> FALSE | AC6: =IF(O6="","",EXACT(O6,AK6)) -> FALSE | AD6: =IF(P6="","",EXACT(P6,AL6)) -> FALSE
A7: 5 | B7: ユーザ管理 | C7: 2 | D7: 1 | E7: NULL | F7: NULL | G7: NULL | H7: 〇 | I7: 不可 | J7: 5 | K7: ユーザ管理 | L7: 2 | M7: 1 | N7: NULL | O7: NULL | P7: NULL | R7: INSERT INTO | S7: MST_DEAL_TBL | T7: VALUES( | U7: =J7&" , "&"'"&K7&"'"&" , "&L7&" , "&M7&" , "&N7&" , "&O7&" , "&P7 -> 5 , 'ユーザ管理' , 2 , 1 , NULL , NULL , NULL | V7: ); | X7: =IF(J7="","",EXACT(J7,AF7)) -> FALSE | Y7: =IF(K7="","",EXACT(K7,AG7)) -> FALSE | Z7: =IF(L7="","",EXACT(L7,AH7)) -> FALSE | AA7: =IF(M7="","",EXACT(M7,AI7)) -> FALSE | AB7: =IF(N7="","",EXACT(N7,AJ7)) -> FALSE | AC7: =IF(O7="","",EXACT(O7,AK7)) -> FALSE | AD7: =IF(P7="","",EXACT(P7,AL7)) -> FALSE
A8: 6 | B8: 本人確認 | C8: 3 | D8: 1 | E8: NULL | F8: NULL | G8: NULL | H8: 〇 | I8: 不可 | J8: 6 | K8: 本人確認 | L8: 3 | M8: 1 | N8: NULL | O8: NULL | P8: NULL | R8: INSERT INTO | S8: MST_DEAL_TBL | T8: VALUES( | U8: =J8&" , "&"'"&K8&"'"&" , "&L8&" , "&M8&" , "&N8&" , "&O8&" , "&P8 -> 6 , '本人確認' , 3 , 1 , NULL , NULL , NULL | V8: ); | X8: =IF(J8="","",EXACT(J8,AF8)) -> FALSE | Y8: =IF(K8="","",EXACT(K8,AG8)) -> FALSE | Z8: =IF(L8="","",EXACT(L8,AH8)) -> FALSE | AA8: =IF(M8="","",EXACT(M8,AI8)) -> FALSE | AB8: =IF(N8="","",EXACT(N8,AJ8)) -> FALSE | AC8: =IF(O8="","",EXACT(O8,AK8)) -> FALSE | AD8: =IF(P8="","",EXACT(P8,AL8)) -> FALSE
A9: 7 | B9: 本人確認仕掛照会 | C9: 3 | D9: 1 | E9: NULL | F9: NULL | G9: NULL | H9: 〇 | I9: 不可 | J9: 7 | K9: 本人確認仕掛照会 | L9: 3 | M9: 1 | N9: NULL | O9: NULL | P9: NULL | R9: INSERT INTO | S9: MST_DEAL_TBL | T9: VALUES( | U9: =J9&" , "&"'"&K9&"'"&" , "&L9&" , "&M9&" , "&N9&" , "&O9&" , "&P9 -> 7 , '本人確認仕掛照会' , 3 , 1 , NULL , NULL , NULL | V9: ); | X9: =IF(J9="","",EXACT(J9,AF9)) -> FALSE | Y9: =IF(K9="","",EXACT(K9,AG9)) -> FALSE | Z9: =IF(L9="","",EXACT(L9,AH9)) -> FALSE | AA9: =IF(M9="","",EXACT(M9,AI9)) -> FALSE | AB9: =IF(N9="","",EXACT(N9,AJ9)) -> FALSE | AC9: =IF(O9="","",EXACT(O9,AK9)) -> FALSE | AD9: =IF(P9="","",EXACT(P9,AL9)) -> FALSE
A10: 8 | B10: 判定履歴照会 | C10: 3 | D10: 1 | E10: NULL | F10: NULL | G10: NULL | H10: 〇 | I10: 不可 | J10: 8 | K10: 判定履歴照会 | L10: 3 | M10: 1 | N10: NULL | O10: NULL | P10: NULL | R10: INSERT INTO | S10: MST_DEAL_TBL | T10: VALUES( | U10: =J10&" , "&"'"&K10&"'"&" , "&L10&" , "&M10&" , "&N10&" , "&O10&" , "&P10 -> 8 , '判定履歴照会' , 3 , 1 , NULL , NULL , NULL | V10: ); | X10: =IF(J10="","",EXACT(J10,AF10)) -> FALSE | Y10: =IF(K10="","",EXACT(K10,AG10)) -> FALSE | Z10: =IF(L10="","",EXACT(L10,AH10)) -> FALSE | AA10: =IF(M10="","",EXACT(M10,AI10)) -> FALSE | AB10: =IF(N10="","",EXACT(N10,AJ10)) -> FALSE | AC10: =IF(O10="","",EXACT(O10,AK10)) -> FALSE | AD10: =IF(P10="","",EXACT(P10,AL10)) -> FALSE
A11: 9 | B11: 操作ログ照会 | C11: 2 | D11: 1 | E11: NULL | F11: NULL | G11: NULL | H11: 〇 | I11: 不可 | J11: 9 | K11: 操作ログ照会 | L11: 2 | M11: 1 | N11: NULL | O11: NULL | P11: NULL | R11: INSERT INTO | S11: MST_DEAL_TBL | T11: VALUES( | U11: =J11&" , "&"'"&K11&"'"&" , "&L11&" , "&M11&" , "&N11&" , "&O11&" , "&P11 -> 9 , '操作ログ照会' , 2 , 1 , NULL , NULL , NULL | V11: ); | X11: =IF(J11="","",EXACT(J11,AF11)) -> FALSE | Y11: =IF(K11="","",EXACT(K11,AG11)) -> FALSE | Z11: =IF(L11="","",EXACT(L11,AH11)) -> FALSE | AA11: =IF(M11="","",EXACT(M11,AI11)) -> FALSE | AB11: =IF(N11="","",EXACT(N11,AJ11)) -> FALSE | AC11: =IF(O11="","",EXACT(O11,AK11)) -> FALSE | AD11: =IF(P11="","",EXACT(P11,AL11)) -> FALSE
A12: 10 | B12: 未判定照会 | C12: 4 | D12: 1 | E12: NULL | F12: NULL | G12: NULL | H12: 〇 | I12: 不可 | J12: 10 | K12: 未判定照会 | L12: 4 | M12: 1 | N12: NULL | O12: NULL | P12: NULL | R12: INSERT INTO | S12: MST_DEAL_TBL | T12: VALUES( | U12: =J12&" , "&"'"&K12&"'"&" , "&L12&" , "&M12&" , "&N12&" , "&O12&" , "&P12 -> 10 , '未判定照会' , 4 , 1 , NULL , NULL , NULL | V12: ); | X12: =IF(J12="","",EXACT(J12,AF12)) -> FALSE | Y12: =IF(K12="","",EXACT(K12,AG12)) -> FALSE | Z12: =IF(L12="","",EXACT(L12,AH12)) -> FALSE | AA12: =IF(M12="","",EXACT(M12,AI12)) -> FALSE | AB12: =IF(N12="","",EXACT(N12,AJ12)) -> FALSE | AC12: =IF(O12="","",EXACT(O12,AK12)) -> FALSE | AD12: =IF(P12="","",EXACT(P12,AL12)) -> FALSE
A13: 11 | B13: 判定済照会 | C13: 4 | D13: 1 | E13: NULL | F13: NULL | G13: NULL | H13: 〇 | I13: 不可 | J13: 11 | K13: 判定済照会 | L13: 4 | M13: 1 | N13: NULL | O13: NULL | P13: NULL | R13: INSERT INTO | S13: MST_DEAL_TBL | T13: VALUES( | U13: =J13&" , "&"'"&K13&"'"&" , "&L13&" , "&M13&" , "&N13&" , "&O13&" , "&P13 -> 11 , '判定済照会' , 4 , 1 , NULL , NULL , NULL | V13: ); | X13: =IF(J13="","",EXACT(J13,AF13)) -> FALSE | Y13: =IF(K13="","",EXACT(K13,AG13)) -> FALSE | Z13: =IF(L13="","",EXACT(L13,AH13)) -> FALSE | AA13: =IF(M13="","",EXACT(M13,AI13)) -> FALSE | AB13: =IF(N13="","",EXACT(N13,AJ13)) -> FALSE | AC13: =IF(O13="","",EXACT(O13,AK13)) -> FALSE | AD13: =IF(P13="","",EXACT(P13,AL13)) -> FALSE
A14: 12 | B14: ファイル処理状況照会 | C14: 4 | D14: 1 | E14: NULL | F14: NULL | G14: NULL | H14: 〇 | I14: 不可 | J14: 12 | K14: ファイル処理状況照会 | L14: 4 | M14: 1 | N14: NULL | O14: NULL | P14: NULL | R14: INSERT INTO | S14: MST_DEAL_TBL | T14: VALUES( | U14: =J14&" , "&"'"&K14&"'"&" , "&L14&" , "&M14&" , "&N14&" , "&O14&" , "&P14 -> 12 , 'ファイル処理状況照会' , 4 , 1 , NULL , NULL , NULL | V14: ); | X14: =IF(J14="","",EXACT(J14,AF14)) -> FALSE | Y14: =IF(K14="","",EXACT(K14,AG14)) -> FALSE | Z14: =IF(L14="","",EXACT(L14,AH14)) -> FALSE | AA14: =IF(M14="","",EXACT(M14,AI14)) -> FALSE | AB14: =IF(N14="","",EXACT(N14,AJ14)) -> FALSE | AC14: =IF(O14="","",EXACT(O14,AK14)) -> FALSE | AD14: =IF(P14="","",EXACT(P14,AL14)) -> FALSE
... A17: 15 | B17: 判定済照会（連動） | C17: 5 | D17: 1 | E17: NULL | F17: NULL | G17: NULL | H17: 〇 | I17: 不可 | J17: 15 | K17: 判定済照会（連動） | L17: 5 | M17: 1 | N17: NULL | O17: NULL | P17: NULL | R17: INSERT INTO | S17: MST_DEAL_TBL | T17: VALUES( | U17: =J17&" , "&"'"&K17&"'"&" , "&L17&" , "&M17&" , "&N17&" , "&O17&" , "&P17 -> 15 , '判定済照会（連動）' , 5 , 1 , NULL , NULL , NULL | V17: ); | X17: =IF(J17="","",EXACT(J17,AF17)) -> FALSE | Y17: =IF(K17="","",EXACT(K17,AG17)) -> FALSE | Z17: =IF(L17="","",EXACT(L17,AH17)) -> FALSE | AA17: =IF(M17="","",EXACT(M17,AI17)) -> FALSE | AB17: =IF(N17="","",EXACT(N17,AJ17)) -> FALSE | AC17: =IF(O17="","",EXACT(O17,AK17)) -> FALSE | AD17: =IF(P17="","",EXACT(P17,AL17)) -> FALSE
A18: 16 | B18: 共通リスト登録日照会 | C18: 2 | D18: 1 | E18: NULL | F18: NULL | G18: NULL | H18: × | I18: 不可 | Q18: PKGでは廃止したメニュー | R18: INSERT INTO | S18: MST_DEAL_TBL | T18: VALUES( | U18: =J18&" , "&"'"&K18&"'"&" , "&L18&" , "&M18&" , "&N18&" , "&O18&" , "&P18 -> , '' , , , , , | V18: ); | X18: =IF(J18="","",EXACT(J18,AF18)) | Y18: =IF(K18="","",EXACT(K18,AG18)) | Z18: =IF(L18="","",EXACT(L18,AH18)) | AA18: =IF(M18="","",EXACT(M18,AI18)) | AB18: =IF(N18="","",EXACT(N18,AJ18)) | AC18: =IF(O18="","",EXACT(O18,AK18)) | AD18: =IF(P18="","",EXACT(P18,AL18))
A19: 17 | B19: URL連携フィルタリング | C19: 3 | D19: 1 | E19: NULL | F19: NULL | G19: NULL | H19: 〇 | I19: 不可 | J19: 17 | K19: URL連携フィルタリング | L19: 3 | M19: 1 | N19: NULL | O19: NULL | P19: NULL | R19: INSERT INTO | S19: MST_DEAL_TBL | T19: VALUES( | U19: =J19&" , "&"'"&K19&"'"&" , "&L19&" , "&M19&" , "&N19&" , "&O19&" , "&P19 -> 17 , 'URL連携フィルタリング' , 3 , 1 , NULL , NULL , NULL | V19: ); | X19: =IF(J19="","",EXACT(J19,AF19)) -> FALSE | Y19: =IF(K19="","",EXACT(K19,AG19)) -> FALSE | Z19: =IF(L19="","",EXACT(L19,AH19)) -> FALSE | AA19: =IF(M19="","",EXACT(M19,AI19)) -> FALSE | AB19: =IF(N19="","",EXACT(N19,AJ19)) -> FALSE | AC19: =IF(O19="","",EXACT(O19,AK19)) -> FALSE | AD19: =IF(P19="","",EXACT(P19,AL19)) -> FALSE
