Workbook

Sheet Sheet0_サマリー
A1: 区分 | B1: 件数 | C1: 備考
A2: ヒアリング項目総数 | B2: =COUNTA(Sheet1_試験追跡!C2:C200) | C2: Sheet1 のヒアリング項目の数
A3: 試験確認済 | B3: =COUNTIF(Sheet1_試験追跡!I2:I200,"○") | C3: A 判定が ○
A4: 試験漏れ | B4: =COUNTIF(Sheet1_試験追跡!I2:I200,"×") | C4: A 判定が ×（試験項目なし／結果相違）
A5: 資材一致 | B5: =COUNTIF(Sheet2_資材追跡!H2:H200,"○") | C5: B 判定が ○
A6: 要確認 | B6: =COUNTIF(Sheet1_試験追跡!I2:I200,"△")+COUNTIF(Sheet2_資材追跡!H2:H200,"△") | C6: A・B の △ 合計
A7: A 未判定 | B7: =COUNTA(Sheet1_試験追跡!C2:C200)-COUNTA(Sheet1_試験追跡!I2:I200) | C7: 判定が空のもの
A8: B 未判定 | B8: =COUNTA(Sheet2_資材追跡!C2:C200)-COUNTA(Sheet2_資材追跡!H2:H200) | C8: 判定が空のもの
A9: SCL確認状況 | B9: 5本すべて読了 | C9: #1 93/93・#2 33/33・#3 25/25・#4 28/28・#5 73/73
A10: 試験ケース総数 | B10: =COUNTA(Sheet3_試験ケース!C2:C400) | C10: Sheet3 の行数（SCL5本の合計）
A11: ヒアリングに紐づけ済 | B11: =COUNTIF(Sheet1_試験追跡!M2:M200,"あり") | C11: Sheet1 の M 判定が「あり」
A12: 試験項目なし（式判定） | B12: =COUNTIF(Sheet1_試験追跡!M2:M200,"試験項目なし") | C12: Sheet3 に対応ケースが1件も無いヒアリング項目
A14: ■ 指摘候補（SCL側）
A15: ① | B15: ケース74 に「DJ OFAC/企業リスト」の記載が無い。51・58・62 にはある → 反映漏れの可能性
A16: ②【解消】 | B16: 『リスク管理部』と『リスク管理部以外』の権限差分 → SCL#2 ケース25・30 で検証済。管理メニューが リスク管理部=3つ／それ以外・担当者=パスワード変更のみ
A17: ③ | B17: ケース75 が「※手順不可」。実施件数の −3 のうちの1件。理由と代替確認を要確認
A18: ④ | B18: A-12（本人確認で使うID情報の表示文字列・表示順）が、検証ポイント「本人確認」の SCL に無い
A19: ⑤ | B19: ヒアリングは L&F管理者（リスク管理部）のみだが、SCL は L&Fプロファイル3種を検証。ヒアリングシートの項目漏れでは
A20: ⑥ | B20: SCL は検証ポイントごとに別ファイル。1本だけ見て「漏れ」と判断しない（#1の所見2が#2で解消した実例）
A21: ⑦ | B21: 管理機能は会社をまたいで見える（SCL#2 ケース09「★横浜ユーザも表示される」）。本人確認では分離。意図どおりか要確認
A22: ⑧ | B22: ヒアリングのBC照合設定（英字名称NGE79／電話番号FME100／ID情報FME100／国内住所LSE88）がSCL#1ケース27〜35で未確認。名称・フリガナ・生年月日のみ
A23: ⑨ | B23: ★強化：2026/06廃止の「警察庁（IB）」が #1 でしか取消されていない。#3（更新対象リスト）#4（該当リスト一覧 ケース05・09）には残存。3本中2本で未反映
A24: ⑩ | B24: SCL#3 ケース08「取消」の想定結果が『処理状態が取込済になること』。ケース10（タスク実行）と同一文。取消なら「取込済」にはならないはず。コピペミスの可能性
A26: 権限マトリクス | B26: 管理者(ﾘｽｸ管理部)=全部可／管理者(それ以外)=本人確認の判定のみ可／担当者=閲覧のみ。3つのSCLを合わせて確定
A27: ⑪ | B27: SCL#4（SOAP）は実施日・結果が空欄に見える。未実施の可能性。結果が無いと「試験結果はヒアシ通りか」を確認できない
... A35: ⑲ | B35: バッチフィルタリングだけ「リスク管理部以外」も全4メニュー使える（ケース53）。管理・リスト管理では差があった。機能ごとに権限設計が違うが意図どおりか

Sheet Sheet1_試験追跡
A1: No | B1: 区分(赤枠/青枠) | C1: ヒアリング項目 | D1: ヒアリングシート該当箇所 | E1: 備考 | F1: 試験項目No | G1: 試験項目内容 | H1: 試験結果 | I1: 判定(○/△/×) | J1: 確認メモ | K1: 紐づく試験ケース数 | L1: 紐づく試験ケース | M1: 落とし込み判定
A2: A-01 | B2: 赤枠 | C2: 横浜サーバへの2ファイルは別々に送信し、HULFT-IDをシステム毎に設定する | D2: ヒアリングシート1部 4-1 | E2: 対象ファイルID：U2KJX001、U2KJX002。4/27 Mtgで、弊社→横浜サーバへ2ファイルを別々に送信し、HULFT-IDはシステム毎に設定したい旨を確認。 | I2: △ | J2: 【SCL 5本（本人確認93／管理33／リスト管理25／SOAP28／バッチ73）すべて読了 した結果】 HULFT の連携設定。画面試験ではなく**設定ファイル側で確認する性質**。 A側（試験）に項目が無いのは妥当な可能性が高い。 → B（資材追跡）で HULFT 設定を確認する。 | K2: =COUNTIF(Sheet3_試験ケース!$H:$H,"*"&$A2&"*") | M2: =IF(K2=0,"試験項目なし","あり")
A3: A-02 | B3: 赤枠 | C3: U2KJX001（顧客開設・変更情報）の配信周期を「四半期」、連携時刻を「12:30:00」とする | D3: ヒアリングシート1部 4-1 | E3: 対象ファイルID：U2KJX001。3) HULFT連携時間／バッチフィルタリングインターフェース。 | I3: △ | J3: 【SCL 5本（本人確認93／管理33／リスト管理25／SOAP28／バッチ73）すべて読了 した結果】 同上。配信周期「四半期」・連携時刻「12:30:00」は HULFT の設定値。 → B（資材追跡）で確認する。 | K3: =COUNTIF(Sheet3_試験ケース!$H:$H,"*"&$A3&"*") | M3: =IF(K3=0,"試験項目なし","あり")
A4: A-03 | B4: 赤枠 | C4: U2KJX002（顧客開設・変更情報）の配信周期を「四半期」、連携時刻を「12:30:00」とする | D4: ヒアリングシート1部 4-1 | E4: 対象ファイルID：U2KJX002。3) HULFT連携時間／バッチフィルタリングインターフェース。 | I4: △ | J4: 【SCL 5本（本人確認93／管理33／リスト管理25／SOAP28／バッチ73）すべて読了 した結果】 同上（U2KJX002）。→ B（資材追跡）で確認する。 | K4: =COUNTIF(Sheet3_試験ケース!$H:$H,"*"&$A4&"*") | M4: =IF(K4=0,"試験項目なし","あり")
A5: A-04 | B5: 赤枠 | C5: 横浜銀行事務部では、BFILE_CINFOを除く対象リストを利用する | D5: ヒアリングシート2部 3-2-3 | F5: SCL_変更機能検証_本人確認（93ケース読了） 横浜側 09・12・17・20 L&F側 26・39・51・58・62・74・81・85 SCL_変更機能検証_SOAP ケース05・09（横浜側／L&F側は未確認） SCL_変更機能検証_バッチフィルタリング ケース09・13 SCL_変更機能検証_バッチフィルタリング ケース18・22（横浜）・29（L&F） | G5: 《横浜側＝出ないこと》 09・12（YOKOHAMA_OTHER_ADMIN）／17・20（YOKOHAMA_OTHER） 「横浜花子」でフィルタリング → 該当リスト一覧に 『BファイルC情報』は表示されないこと。 《L&F側＝出ること》 26・39・51（LF_ADMIN_RISK）「えるえふ太郎」→ 該当リスト一覧に『BファイルC情報』が表示されること。 | H5: OK（2026/9/28 実施・再鑑とも OK／7ケース） | I5: ○ | J5: ◎ 落とし込み済み。横浜2プロファイル×2ルートで「出ない」、 L&Fプロファイル3ルートで「出る」。裏表そろっている。 【追記】5つのプロファイルすべてで確認されている。 横浜2種で「出ない」、L&F2種で「出る」。 【追記・93ケース読了】6プロファイルすべてで確認。 【追記・SCL#4（SOAP）】 SOAP連携（リアルフィルタリング）でも横浜プロファイルの 該当リスト一覧が確認されている（ケース05・09）。 ★ただし「BファイルC情報は表示されないこと」の記載があるかは 画面で切れており未確認。L&Fプロファイル分も未確認。 ★SCL#4 は実施日・結果が空欄に見える（未実施の可能性）。 【訂正・SCL#4 読了】 SOAP経路（リアルフィルタリング）は **横浜銀行専用**で、 L&F の3プロファイルすべてで「未判定照会（連動）」が 表示されない（ケース21・24・27）。 → A-04/A-05 は SOAP経路には適用されない。 【追記・SCL#5（バッチ）】 バッチ経路でも横浜側で BファイルC情報 が表示されないことを確認 （ケース09・13）。 【追記・SCL#5（バッチ）】バッチ経路でも裏表そろって確認されている。 横浜側（18・22）… BファイルC情報 は表示されないこと L&F側（29） … BファイルC情報 が表示されること | K5: =COUNTIF(Sheet3_試験ケース!$H:$H,"*"&$A5&"*") | L5: 01#09 01#12 01#17 01#20 01#26 01#39 01#51 01#58 01#62 01#74 01#81 01#85 04#05 04#09 05#09 05#13 05#18 05#22 05#29 05#69 | M5: =IF(K5=0,"試験項目なし","あり")
A6: A-05 | B6: 赤枠 | C6: L&F横浜店では、MOF、JPI、DJ_SHIPSを除く対象リストを利用する | D6: ヒアリングシート2部 3-2-3 | F6: SCL_変更機能検証_本人確認（93ケース読了） ケース26・39・51・58・62・74・81・85 SCL_変更機能検証_バッチフィルタリング ケース29 | G6: LF_ADMIN_RISK で法人「えるえふ太郎」をフィルタリング。 想定結果の『下記は表示されないこと』に ・財務省 ・JCIF PEPs ・DJ 船舶リスト が明記されている（3ルートで確認）。 | H6: OK（2026/9/28 実施・再鑑とも OK／3ケース） | I6: ○ | J6: ◎ ヒアリングと完全一致。 MOF → 財務省 ／ JPI → JCIF PEPs ／ DJ_SHIPS → DJ 船舶リスト 【追記】LF_ADMIN_RISK（26・39・51）と LF_ADMIN_RISK_EXC（58・62・74）の両方で確認済み。 ★ただしケース74 に「DJ OFAC/企業リスト」の記載が無い。 ケース51・58・62 にはある。SCL の反映漏れの可能性あり（要確認）。 【追記・93ケース読了】L&F3プロファイル（管理者2種＋担当者）で確認。 【追記・SCL#5（バッチ）】★バッチ経路でも確認されていた。 ケース29（LF_ADMIN_RISK）の『下記は表示されないこと』に ・財務省（MOF） ・JCIF PEPs（JPI） ・DJ 船舶リスト（DJ_SHIPS） → 本人確認（#1）とバッチ（#5）の両経路で確認済み。 | K6: =COUNTIF(Sheet3_試験ケース!$H:$H,"*"&$A6&"*") | L6: 01#09 01#12 01#17 01#20 01#26 01#39 01#51 01#58 01#62 01#74 01#81 01#85 05#29 05#69 | M6: =IF(K6=0,"試験項目なし","あり")
A7: A-06 | B7: 赤枠 | C7: 部店ごとのフィルタリング対象リストの使い分けは行わない | D7: ヒアリングシート2部 3-2-3 | I7: △ | J7: 【SCL 5本（本人確認93／管理33／リスト管理25／SOAP28／バッチ73）すべて読了 した結果】 「使い分けを行わない」＝**ないことの確認**。試験項目にしにくい性質。 → B（資材追跡）で 25_部店フィルタリング設定 を見て、 全部店が同一設定であることを確認するのが自然。 | K7: =COUNTIF(Sheet3_試験ケース!$H:$H,"*"&$A7&"*") | L7: 01#11 | M7: =IF(K7=0,"試験項目なし","あり")
A8: A-07 | B8: 赤枠 | C8: 判定情報のプルダウンに表示する補助コメントおよび表示順を設定する | D8: ヒアリングシート2部 3-2-4 | E8: 表示内容および表示順は以下の通り。 1：該当あり（コンプラ先） 2：該当あり（マーク先） 3：該当あり（C情報） 4：該当あり（その他） 5：該当なし 6：取消し | F8: SCL_変更機能検証_本人確認 ケース40・63（主） ケース43・45・66・68 SCL_変更機能検証_バッチフィルタリング ケース42・44 | G8: 40 補助コメント 補助コメントのプルダウンに下記が表示されること 該当あり（コンプラ先） 該当あり（マーク先） 該当あり（C情報） ←赤字で3番目に移動 該当あり（その他） 該当なし 取消し ※SCL上「並び順修正」として、C情報 を6番目から3番目へ変更した跡あり。 43 判定実施（プルダウン選択） 選択した補助コメントが判定済み照会画面に表示されること。 | H8: OK（2026/9/28 実施・再鑑とも OK） | I8: ○ | J8: ★不備あり（指摘候補⑰） ◎ ヒアリング備考の 1〜6 の並びと完全一致。 1 該当あり（コンプラ先）／2 該当あり（マーク先）／3 該当あり（C情報） 4 該当あり（その他）／5 該当なし／6 取消し 表示内容だけでなく**表示順まで**試験項目に落ちている。 しかも SCL 側で並び順の誤りが修正されており、是正済みの状態。 【追記】ケース63 で2つ目のL&Fプロファイルでも確認。 判定実施は 43/45/66/68 の4ケースで 「チェック有無 × プルダウン／テキスト」の4通りを網羅している。 【追記・SCL#5】バッチ経路でも補助コメントの プルダウン選択（42）とテキスト入力（44）を確認。 【追記・SCL#5 ケース58】★重要 補助コメントの並び順が**ヒアリングと一致していない**。 ヒアリング 1 コンプラ先/2 マーク先/**3 C情報**/4 その他/5 該当なし/6 取消し #1 ケース40 上記どおり（並び順修正済） #5 ケース58 コンプラ先/マーク先/その他/該当なし/**C情報**/取消し → #1 の修正が #5 に未反映。このまま試験すると、 正しい画面を見て NG と判定してしまう。**是正必要。** | K8: =COUNTIF(Sheet3_試験ケース!$H:$H,"*"&$A8&"*") | L8: 01#40 01#43 01#45 01#63 01#66 01#68 05#42 05#44 05#58 | M8: =IF(K8=0,"試験項目なし","あり")
A9: A-08 | B9: 赤枠 | C9: ファイル記号O～Tでは、MOF、JP、DJ_SHIPSを除く対象リストを利用する | D9: ヒアリングシート2部 3-3-3 | E9: 備考： ファイル記号O～Tのリスト利用設定： OFAC：○ MOF：× JP：× NPA：○ NPC：○ NPI：○ ASI：○ ASC：○ DJ_SEISAI：○ DJ_SHIPS：× DJ_GAIKOKU_PEPS：○ DJ_KOKUNAI_PEPS：○ ZENGIN_SEIHO：○ ZENGIN_SONPO：○ ORIGINAL：○ BFILE_CINFO：○ | I9: × | J9: 【SCL 5本（本人確認93／管理33／リスト管理25／SOAP28／バッチ73）すべて読了 した結果】 **5本すべてに該当する試験項目が無い。** ファイル記号O〜T のリスト利用設定（OFAC○ MOF× JP× NPA○ …）は フィルタリングの挙動に直結するため、試験できるはず。 特にバッチフィルタリング（#5・73ケース）にあると予想したが無かった。 → **落とし込み漏れの可能性が高い。** | K9: =COUNTIF(Sheet3_試験ケース!$H:$H,"*"&$A9&"*") | M9: =IF(K9=0,"試験項目なし","あり")
A10: A-09 | B10: 赤字変更箇所 | C10: 対象業務では前回判定を自動的に適用する | D10: ヒアリングシート2部 3-5-5 | E10: 前回判定適用設定はいずれも「有」。 BFZ：バッチフィルタリング（全銀） BFS：バッチフィルタリング（差分） DSF：DMその他（一括フィルタリング） SHF：新規顧客開設・届出情報変更 | I10: × | J10: 【SCL 5本（本人確認93／管理33／リスト管理25／SOAP28／バッチ73）すべて読了 した結果】 **5本すべてに該当する試験項目が無い。** 前回判定適用（BFZ/BFS/DSF/SHF いずれも「有」）は 判定画面の挙動に直結するため、試験できるはず。 → **落とし込み漏れの可能性が高い。** | K10: =COUNTIF(Sheet3_試験ケース!$H:$H,"*"&$A10&"*") | M10: =IF(K10=0,"試験項目なし","あり")
A11: A-10 | C11: Oculus-monitorに連携するモニタリング画面表示リスト名を設定する | D11: ヒアリングシート2部 3-7 | E11: BファイルC情報はモニタリング画面表示リストへの追加不要 | I11: △ | J11: 【SCL 5本（本人確認93／管理33／リスト管理25／SOAP28／バッチ73）すべて読了 した結果】 Oculus-monitor への連携。**monitor 側の SCL**にある可能性がある。 今回確認した5本は filter 側のみ。 → monitor 側の試験資料の有無を確認する。 | K11: =COUNTIF(Sheet3_試験ケース!$H:$H,"*"&$A11&"*") | M11: =IF(K11=0,"試験項目なし","あり")
A12: A-11 | B12: 赤枠 | C12: L&Fで使用するCIF情報ファイルのファイル記号O～Tを、各業務のファイル属性として設定する | D12: ヒアリングシート2部 4-1-4 | E12: O：LF-LOANS+ P：LF-OLION Q：LF-NEON R：LF-試着先以外 S：LF-損害金 T：LF-DM送付先一覧 | I12: × | J12: 【SCL 5本（本人確認93／管理33／リスト管理25／SOAP28／バッチ73）すべて読了 した結果】 **5本すべてに該当する試験項目が無い。** ファイル記号O〜T のファイル属性（O：LF-LOANS+ 等）は 画面表示や処理分岐に影響するため、試験できるはず。 → **落とし込み漏れの可能性が高い。** | K12: =COUNTIF(Sheet3_試験ケース!$H:$H,"*"&$A12&"*") | M12: =IF(K12=0,"試験項目なし","あり")
A13: A-12 | B13: 赤枠 | C13: 本人確認等で使用するID情報の表示文字列および表示順は既存設定を使用し、L&Fでの追加設定は行わない | D13: ヒアリングシート2部 4-1-4 | E13: L&Fでの追加設定はなし | I13: × | J13: 【SCL 5本（本人確認93／管理33／リスト管理25／SOAP28／バッチ73）すべて読了 した結果】 ★**最も確度が高い落とし込み漏れ。** SCL#1 は検証ポイントが「**本人確認**」そのもので93ケースあるが、 ID情報の表示文字列・表示順を確認する試験項目が無い。 本来ここにあるべき項目。 ※ケース40・58 は『補助コメント』であって『ID情報』ではない。混同注意。 | K13: =COUNTIF(Sheet3_試験ケース!$H:$H,"*"&$A13&"*") | M13: =IF(K13=0,"試験項目なし","あり")
A14: A-13 | B14: 赤枠 | C14: BFILE_CINFO（BファイルC情報）のリスト基本情報を設定する | D14: ヒアリングシート2部_リスト設定 | F14: SCL_変更機能検証_本人確認 ケース03・26・27〜35 SCL_変更機能検証_リスト管理 ケース06・07・09 SCL_変更機能検証_バッチフィルタリング ケース03・29・30〜36 | G14: 03 リストアップロード－L&F … BファイルC情報.csv を登録 26 フィルタリング実行（有） … 該当リスト一覧に表示されること 27〜35 フィルタリング結果確認（9ケース） 各レコードで赤字＋太字で強調される照合項目を確認 LF00000001 名称／フリガナ／生年月日 LF00000002 名称／生年月日 LF00000003 名称／生年月日 LF00000004 生年月日 LF00000007 フリガナ／生年月日 LF00000019 名称／フリガナ LF00000020 名称 LF00000021 名称 LF00000025 フリガナ 《SCL_変更機能検証_リスト管理》 06 更新対象リスト プルダウンに『BファイルC情報』が表示されること 07・09 ファイルアップロード 更新対象リスト＝BファイルC情報／更新種別＝一括 を選び 「BファイルC情報.csv」をアップロード → アップロード履歴一覧に「処理中」で追加されること 10 タスク実行（リストアップロード制御） → 処理状態が「取込済」になること | H14: OK（2026/9/28 実施・再鑑とも OK／11ケース） | I14: ○ | J14: ◎ 登録・表示・照合の3段階。照合項目（名称・フリガナ・生年月日）の 組み合わせを9パターンで網羅している。 ※設定値そのもの（マスタSQL・実機DB）は B 側で確認する。 【追記・SCL#3】登録のルートがより詳細に確認されている。 #1 ケース03 は画面からのアップロードのみだったが、 #3 では 更新対象リストへの登録 → 一括アップロード → タスク実行 → 取込済 まで通しで確認している。 【追記・SCL#5】バッチ経路でも照合項目を7パターン確認（30〜36）。 ★ただし ケース33（LF00000004）の強調項目が #1 ケース30 と食い違っている。 #1 ~~フリガナ~~（赤字取消）／生年月日 #5 フリガナ／生年月日 → #1 の修正が #5 に未反映（指摘候補⑭の5点目）。 | K14: =COUNTIF(Sheet3_試験ケース!$H:$H,"*"&$A14&"*") | L14: 01#03 01#26 01#27 01#28 01#29 01#30 01#31 01#32 01#33 01#34 01#35 03#06 03#07 03#09 03#10 05#03 05#30 05#31 05#32 05#33 05#34 05#35 05#36 | M14: =IF(K14=0,"試験項目なし","あり")
A15: A-14 | B15: 赤枠 | C15: L&F管理者（リスク管理部）の権限を設定する | D15: ヒアリングシート2部_プロファイル設定 | F15: SCL_変更機能検証_本人確認 ケース23・55・78（メニュー） ケース81・85・91（権限差分） SCL_変更機能検証_管理 ケース02（管理メニュー）・07（プロファイル一覧） SCL_変更機能検証_リスト管理 ケース02・21・24 SCL_変更機能検証_SOAP ケース21・24・27 SCL_変更機能検証_バッチフィルタリング ケース25 | G15: 23 メニュー確認／LF_ADMIN_RISK ★主たる確認 左メニュー「本人確認」配下に下記が表示されていること ・本人確認 ・本人確認仕掛照会 ・判定履歴照会 47 判定履歴照会 … 実際に遷移でき、一覧画面が表示されること 22 ログイン／03 リスト登録 … 同ユーザで操作できること 《SCL_変更機能検証_管理》 02 メニュー確認（LF_ADMIN_RISK） 「管理」に パスワード変更／ユーザ管理／操作ログ照会 が表示されること 07 プロファイル プルダウンに10種（既存7＋L&F3）が表示されること 25 メニュー確認（LF_ADMIN_RISK_EXC） 「管理」に **パスワード変更のみ** が表示されること 30 メニュー確認（LF_PIC） 「管理」に **パスワード変更のみ** が表示されること 《SCL_変更機能検証_リスト管理》 02 メニュー確認（LF_ADMIN_RISK） 「リスト管理」に 登録済リスト参照／リストアップロード／ ホワイトリスト登録 が表示されること 21 メニュー確認（LF_ADMIN_RISK_EXC） 「リスト管理」が表示されていないこと（要文言確認） 24 メニュー確認（LF_PIC） 「リスト管理」が表示されていないこと | H15: OK（2026/9/28 実施・再鑑とも OK） | I15: ○ | J15: ◎ 権限＝利用できるメニューを列挙して確認し、 さらに各メニューに実際に遷移できることまで確認している。 SCL上も「L&F社様新規プロファイル：L&F管理者（リスク管理部）」として 章立てされている。 ※残課題：ケース02 の指摘で、警察庁（個人）のアップロード実施者が 「リスク管理部門（役席）」ではなく「L&F管理者（リスク管理）」だった件。 権限の割り当て自体は B 側で要確認。 【追記】ケース55 で LF_ADMIN_RISK_EXC（リスク管理部以外）も確認。 ★ただし想定結果は「**『本人確認』に**下記が表示されていること」であり、 本人確認グループの3メニューしか見ていない。 LF_ADMIN_RISK はケース03 でリスト管理も使っているが、 リスト管理など他グループのメニューがプロファイルごとに どう違うかは試験項目に落ちていない。 → 権限の差分確認が漏れている可能性。阿部さんに確認する。 【追記・93ケース読了】所見を一部訂正。 ○ 管理者 ⇔ 担当者 の差分は検証されている（ケース81・85・91） ・リスト情報が表示されないこと（ヒット箇所が不明なこと） ・判定ボタンが表示されないこと ・ボタン名が「判定」→「判定表示」になること → メニューではなく画面要素で権限差分を見ている。 ★ ただし『リスク管理部』と『リスク管理部以外』の差分は未検証。 ケース22〜51 と 54〜76 は想定結果がまったく同じ。 リストアップロードは LF_ADMIN_RISK（ケース03）だけが実施しており、 LF_ADMIN_RISK_EXC で「できないこと」を確認する項目が無い。 → 差があるなら漏れ、差が無いなら分ける理由が不明。要確認。 ★ ヒアリングは A-14『L&F管理者（リスク管理部）の権限』の1件のみだが、 SCL は L&Fプロファイルを3種類検証している。 ヒアリングシートに他プロファイルの項目が無いか要確認 （Sheet1 の A-15〜A-20 が空欄のため）。 【追記・SCL#2（管理）】 ○ ケース02 … 「管理」メニュー（パスワード変更／ユーザ管理／ 操作ログ照会）が表示されることを確認。 → SCL#1 の所見『メニュー確認が本人確認グループのみ』は、 管理グループがこの SCL にあったため**一部解消**。 ◎ ケース07 … プロファイルのプルダウンに10種が列挙され、 L&Fの3種が明記されている。 L&F管理者（リスク管理部） L&F管理者（リスク管理部以外） L&F担当者 ★ ただし『リスク管理部』と『リスク管理部以外』を選んだ時に 何が変わるかは、SCL#1・#2 とも未検証のまま。 ★ ヒアリング（A-14）は「L&F管理者（リスク管理部）」の1件のみ。 ヒアリングシート2部_プロファイル設定 に3種とも 書かれていないか要確認（Sheet1 への拾い漏れの可能性）。 【追記・SCL#2 読了】★指摘候補②は解消。 プロファイル別の「管理」メニュー ﾊﾟｽﾜｰﾄﾞ変更 ﾕｰｻﾞ管理 操作ﾛｸﾞ照会 リスク管理部 ○ ○ ○ リスク管理部以外 ○ × × 担当者 ○ × × → 権限差分は本人確認ではなく**管理メニュー側**に出る設計だった。 SCL#1 だけ見て「差分が未検証」と判断したのは誤りだった。 L&F 3プロファイルの整理 本人確認 判定 ﾘｽﾄ情報 ﾕｰｻﾞ管理 操作ﾛｸﾞ 管理者(ﾘｽｸ管理部) ○ ○ ○ ○ ○ 管理者(それ以外) ○ ○ ○ × × 担当者 ○ × × × × 【追記・SCL#3（リスト管理）】 LF_ADMIN_RISK の「リスト管理」メニュー3つを確認（ケース02）。 → メニュー確認は 本人確認（#1）／管理（#2）／リスト管理（#3）の 3グループすべてで行われている。 ★ ただし #3 で LF_ADMIN_RISK_EXC・LF_PIC の リスト管理メニューを確認しているかは未確認（続きのケース待ち）。 ここが分かると権限マトリクスが完成する。 【追記・SCL#3 読了】★権限マトリクスが完成した。 メニューグループ別 本人確認 管理 リスト管理 管理者(ﾘｽｸ管理部) ○ ○(3つ) ○(3つ) 管理者(それ以外) ○ △(1つ) × 担当者 ○ △(1つ) × 管理△＝パスワード変更のみ／○＝ＰＷ変更・ユーザ管理・操作ログ照会 機能レベル 本人確認 判定 ﾘｽﾄ情報 ﾘｽﾄ管理 ﾕｰｻﾞ管理 操作ﾛｸﾞ 管理者(ﾘｽｸ管理部) ○ ○ ○ ○ ○ ○ 管理者(それ以外) ○ ○ ○ × × × 担当者 ○ × × × × × ★ SCL#1 で指摘した『EXC がリスト登録できないことの確認が無い』は、 SCL#3 ケース21 で確認されていた。→ 解消。 ※ ケース21 の文言は画面右端で切れていたため実ファイルで要確認 （ケース構成が ログイン→メニュー確認→ログアウト の3つだけなので 「表示されていないこと」とほぼ断定できる）。 【追記・SCL#4】メニューグループが4つそろった。 本人確認 管理 ﾘｽﾄ管理 ﾘｱﾙﾌｨﾙﾀﾘﾝｸﾞ 管理者(ﾘｽｸ管理部) ○ ○(3) ○(3) × 管理者(それ以外) ○ △(1) × × 担当者 ○ △(1) × × 管理△＝パスワード変更のみ → L&F は リアルフィルタリング（SOAP連携）を一切使わない。 【追記・SCL#5】5つ目のメニューグループ「バッチフィルタリング」。 未判定照会／判定済照会／ファイル処理状況照会／検索対象者一覧アップロード ★ケース46 で「バッチフィルタリング－判定履歴照会」を使っているが、 ケース25 のメニュー一覧（4つ）に入っていない。記載漏れの可能性。 【追記・SCL#5 読了】メニューグループが5つそろった。 本人確認 管理 ﾘｽﾄ管理 ﾘｱﾙﾌｨﾙﾀ ﾊﾞｯﾁﾌｨﾙﾀ 管理者(ﾘｽｸ管理部) ○ ○(3) ○(3) × ○(4) 管理者(それ以外) ○ △(1) × × ○(4) 担当者 ○ △(1) × × × ★ バッチフィルタリングだけ「リスク管理部以外」も全機能使える。 機能ごとに権限設計が違う。意図どおりか確認する価値あり。 | K15: =COUNTIF(Sheet3_試験ケース!$H:$H,"*"&$A15&"*") | L15: 01#22 01#23 01#54 01#55 01#77 01#78 01#81 01#85 01#86 01#91 01#92 02#07 03#02 03#21 03#24 05#25 05#53 05#72 | M15: =IF(K15=0,"試験項目なし","あり")
A16: A-15 | B16: 赤枠 | C16: L&Fの部店コードを LF001〜LF025 の25部店で設定する | D16: ヒアリングシート_部店コード | E16: 2026/04/07追加、2026/05/11 L&F様部店。 期限：部店数・部店コードは6/19まで、部店名の変更は7/1まで可能。 マスタ定義：5_部店マスタ／25_部店フィルタリング設定／26_CIFファイルフィルタリング設定 | F16: SCL_変更機能検証_管理 ケース06 | G16: 06 所属部店名／LF_ADMIN_RISK ユーザ管理画面の「所属部店名」プルダウンを表示する。 想定結果：下記L&F部店を含んだリストが表示されること 一括照合用／監査部／経営企画部／業務改革室／人財部 リスク管理部／財務経理部／ITソリューション部 営業戦略部／営業推進部／与信企画室 融資第一部／融資第二部／債権管理部 本店営業第一部／本店営業第二部／本店営業第四部 新宿支店／池袋支店／横浜支店／大阪支店／名古屋支店 仙台支店／福岡支店／広島営業部 | H16: （実施結果はSCL#2のヘッダ未確認） | I16: ○ | J16: ◎ ヒアリングシート_部店コード の LF001〜LF025（25件）と 名称・順番とも完全一致。落とし込みができている。 【新規に識別したヒアリング項目】 A-01〜A-14 に入っていなかったため追加した項目。 マスタ定義：5_部店マスタ／25_部店フィルタリング設定／ 26_CIFファイルフィルタリング設定 ※SCL#2 の実施件数（OK/NG/−）が未確認のため、結果欄は保留。 | K16: =COUNTIF(Sheet3_試験ケース!$H:$H,"*"&$A16&"*") | L16: 02#06 | M16: =IF(K16=0,"試験項目なし","あり")
A17: A-16
A18: A-17
A19: A-18
A20: A-19
A21: A-20

Sheet Sheet2_資材追跡
A1: No | B1: 区分(赤枠/青枠) | C1: ヒアリング内容 | D1: 設計書該当箇所 | E1: マスタSQL | F1: 設定ファイル | G1: 実機DB確認 | H1: 判定(○/△/×) | I1: 備考
A2: B-01 | B2: 赤枠 | C2: 横浜サーバへの2ファイルは別々に送信し、HULFT-IDをシステム毎に設定する | I2: A-01 と対応（ヒアリングシート1部 4-1）
A3: B-02 | B3: 赤枠 | C3: U2KJX001（顧客開設・変更情報）の配信周期を「四半期」、連携時刻を「12:30:00」とする | I3: A-02 と対応（ヒアリングシート1部 4-1）
A4: B-03 | B4: 赤枠 | C4: U2KJX002（顧客開設・変更情報）の配信周期を「四半期」、連携時刻を「12:30:00」とする | I4: A-03 と対応（ヒアリングシート1部 4-1）
A5: B-04 | B5: 赤枠 | C5: 横浜銀行事務部では、BFILE_CINFOを除く対象リストを利用する | I5: A-04 と対応（ヒアリングシート2部 3-2-3） ★確認先の候補（部店コードシートのマスタ定義より） 5_部店マスタ／25_部店フィルタリング設定／26_CIFファイルフィルタリング設定
A6: B-05 | B6: 赤枠 | C6: L&F横浜店では、MOF、JPI、DJ_SHIPSを除く対象リストを利用する | I6: A-05 と対応（ヒアリングシート2部 3-2-3） ★確認先の候補（部店コードシートのマスタ定義より） 5_部店マスタ／25_部店フィルタリング設定／26_CIFファイルフィルタリング設定
A7: B-06 | B7: 赤枠 | C7: 部店ごとのフィルタリング対象リストの使い分けは行わない | I7: A-06 と対応（ヒアリングシート2部 3-2-3） ★確認の向きが逆：部店別の設定が【入っていないこと】を確認する ★確認先の候補（部店コードシートのマスタ定義より） 5_部店マスタ／25_部店フィルタリング設定／26_CIFファイルフィルタリング設定
A8: B-07 | B8: 赤枠 | C8: 判定情報のプルダウンに表示する補助コメントおよび表示順を設定する | I8: A-07 と対応（ヒアリングシート2部 3-2-4）
A9: B-08 | B9: 赤枠 | C9: ファイル記号O～Tでは、MOF、JP、DJ_SHIPSを除く対象リストを利用する | I9: A-08 と対応（ヒアリングシート2部 3-3-3）
A10: B-09 | B10: 赤字変更箇所 | C10: 対象業務では前回判定を自動的に適用する | I10: A-09 と対応（ヒアリングシート2部 3-5-5）
A11: B-10 | C11: Oculus-monitorに連携するモニタリング画面表示リスト名を設定する | I11: A-10 と対応（ヒアリングシート2部 3-7）
A12: B-11 | B12: 赤枠 | C12: L&Fで使用するCIF情報ファイルのファイル記号O～Tを、各業務のファイル属性として設定する | I12: A-11 と対応（ヒアリングシート2部 4-1-4）
A13: B-12 | B13: 赤枠 | C13: 本人確認等で使用するID情報の表示文字列および表示順は既存設定を使用し、L&Fでの追加設定は行わない | I13: A-12 と対応（ヒアリングシート2部 4-1-4） ★確認の向きが逆：L&F用の追加設定が【されていないこと】を確認する
A14: B-13 | B14: 赤枠 | C14: BFILE_CINFO（BファイルC情報）のリスト基本情報を設定する | I14: A-13 と対応（ヒアリングシート2部_フィルタリング設定（オンライン）） ★設定の中身は B-13-01〜B-13-17 に展開した（ヒアリングシート2部_フィルタリング設定（オンライン））。 横ぐし確認は細目の行で行う。
A15: B-13-01 | B15: リスト項目（照合設定） | C15: 【BファイルC情報(BC)】フリガナ／別称（フリガナ） → 名称及び別称 LSE ／ 閾値 88 | I15: ヒアリングシート2部_フィルタリング設定（オンライン） より。B-13 の細目。 ※コメント <20260518 MDLC>「L&F様利用リスト『BファイルC情報』の 設定内容を記載ください」期限 6/19 に対する回答欄。
A16: B-13-02 | B16: リスト項目（照合設定） | C16: 【BファイルC情報(BC)】名称／別称（名称） → 名称及び別称 LSE ／ 閾値 88 | I16: ヒアリングシート2部_フィルタリング設定（オンライン） より。B-13 の細目。 ※コメント <20260518 MDLC>「L&F様利用リスト『BファイルC情報』の 設定内容を記載ください」期限 6/19 に対する回答欄。
A17: B-13-03 | B17: リスト項目（照合設定） | C17: 【BファイルC情報(BC)】英字名称／別称（英字名称） → 名称及び別称 NGE ／ 閾値 79 | I17: ヒアリングシート2部_フィルタリング設定（オンライン） より。B-13 の細目。 ※コメント <20260518 MDLC>「L&F様利用リスト『BファイルC情報』の 設定内容を記載ください」期限 6/19 に対する回答欄。
A18: B-13-04 | B18: リスト項目（照合設定） | C18: 【BファイルC情報(BC)】電話番号 → その他ID情報 FME ／ 閾値 100 | I18: ヒアリングシート2部_フィルタリング設定（オンライン） より。B-13 の細目。 ※コメント <20260518 MDLC>「L&F様利用リスト『BファイルC情報』の 設定内容を記載ください」期限 6/19 に対する回答欄。
A19: B-13-05 | B19: リスト項目（照合設定） | C19: 【BファイルC情報(BC)】ID情報／ID情報2 → ID情報 FME ／ 閾値 100 | I19: ヒアリングシート2部_フィルタリング設定（オンライン） より。B-13 の細目。 ※コメント <20260518 MDLC>「L&F様利用リスト『BファイルC情報』の 設定内容を記載ください」期限 6/19 に対する回答欄。
A20: B-13-06 | B20: リスト項目（照合設定） | C20: 【BファイルC情報(BC)】ID情報／ID情報2 → パスポート番号 FME ／ 閾値 100 | I20: ヒアリングシート2部_フィルタリング設定（オンライン） より。B-13 の細目。 ※コメント <20260518 MDLC>「L&F様利用リスト『BファイルC情報』の 設定内容を記載ください」期限 6/19 に対する回答欄。
A21: B-13-07 | B21: リスト項目（照合設定） | C21: 【BファイルC情報(BC)】ID情報／ID情報2 → その他ID情報 FME ／ 閾値 100 | I21: ヒアリングシート2部_フィルタリング設定（オンライン） より。B-13 の細目。 ※コメント <20260518 MDLC>「L&F様利用リスト『BファイルC情報』の 設定内容を記載ください」期限 6/19 に対する回答欄。
A22: B-13-08 | B22: リスト項目（照合設定） | C22: 【BファイルC情報(BC)】ID情報／ID情報2 → BIC FME ／ 閾値 100 | I22: ヒアリングシート2部_フィルタリング設定（オンライン） より。B-13 の細目。 ※コメント <20260518 MDLC>「L&F様利用リスト『BファイルC情報』の 設定内容を記載ください」期限 6/19 に対する回答欄。
A23: B-13-09 | B23: リスト項目（照合設定） | C23: 【BファイルC情報(BC)】国内住所 → 住所・都市・国 LSE ／ 閾値 88 | I23: ヒアリングシート2部_フィルタリング設定（オンライン） より。B-13 の細目。 ※コメント <20260518 MDLC>「L&F様利用リスト『BファイルC情報』の 設定内容を記載ください」期限 6/19 に対する回答欄。
... A32: B-14 | B32: 赤枠 | C32: L&F管理者（リスク管理部）の権限を設定する | I32: A-14 と対応（ヒアリングシート2部_プロファイル設定）
A33: B-15 | B33: 赤枠 | C33: 【部店コード】L&Fの部店を LF001〜LF025 の25件で設定する LF001 一括照合用 5 LF002 監査部 3 LF003 経営企画部 5 LF004 業務改革室 5 LF005 人財部 3 LF006 リスク管理部 6 LF007 財務経理部 5 LF008 ITソリューション部 10 LF009 営業戦略部 5 LF010 営業推進部 5 LF011 与信企画室 5 LF012 融資第一部 5 LF013 融資第二部 5 LF014 債権管理部 5 LF015 本店営業第一部 7 LF016 本店営業第二部 7 LF017 本店営業第四部 7 LF018 新宿支店 4 LF019 池袋支店 4 LF020 横浜支店 4 LF021 大阪支店 4 LF022 名古屋支店 5 LF023 仙台支店 4 LF024 福岡支店 4 LF025 広島営業部 5 | D33: マスタ定義（ヒアリングシート記載） 5_部店マスタ 25_部店フィルタリング設定 26_CIFファイルフィルタリング設定 | I33: 出典：ヒアリングシート_部店コード（2026/05/11 L&F様部店） 期限：部店数・部店コードは6/19、部店名の変更は7/1まで ★D列の数値（5/3/6/10/7/4 等）の意味は未確認。 ユーザ数か何かと思われる。要確認。 ★この3つのマスタは A-04/A-05/A-06 の確認先にもなる。
A34: B-16
A35: B-17
A36: B-18
A37: B-19
A38: B-20

Sheet Sheet3_試験ケース
A1: No | B1: SCL | C1: ケースNo | D1: ケース名 | E1: 内容・操作 | F1: 想定結果 | G1: 結果 | H1: 対応ヒアリング項目 | I1: SCL整理の記載 | J1: 確認メモ
A2: 1 | B2: 01_本人確認 | C2: 01 | D2: ファイル配置 | E2: CIFファイル・リストファイル・ユーザ情報ファイルを所定の場所に置く / CIF C:\FileRCV\output\0000000138C_YYYYMMDD002.txt / リスト C:\LIST_BATCH\BLACKLIST 配下 / OFAC\sdn.xml / MOF\MOF.csv / JP\PEPs.csv / DJ_SEISAI\DSE.xml / DJ_SHIPS\DSH.xml / DJ_GAIKOKU_PEPS\DGP.xml / DJ_KOKUNAI_PEPS\DKP.xml / ORIGINAL\行内要注意情報.csv / ユーザ情報 C:\FileRCV\input_user\USER0000000138_YYYYMMDD.txt ←赤字＝追加 / 確認すること / ファイルが配置されていること（存在確認のみ） / 抽象化 / 試験の前提準備。機能の検証ではない。 / 結果 / 2026/9/28 OK ／ 再鑑 2026/9/28 OK / 指摘のやりとり / ・リストファイル名までエビデンスで確認できていなかった / ・今後は dir /s "C:\LIST_BATCH\BLACKLIST" の結果をエビデンスにする / ・ユーザ情報ファイルの確認を SCL に追加（阿部）→ 池田 OK | I2: あり
A3: 2 | B3: 01_本人確認 | C3: 02 | D3: リストアップロード－横浜 | E3: http://サーバIP:9080/aml-web/ に RISK_ADMIN_001（会社コード0138）でログイン / リスト管理－リストアップロード画面から下記をアップロード / 警察庁（個人）－凍結口座名義人リスト.csv / 警察庁（法人）－凍結口座名義人リスト法人版.csv / ~~警察庁（IB）－IB不正送金先口座名義人リスト.csv~~ ←赤字で取消＝廃止 / ASI.csv － 全銀協（個人） / ASC.csv － 全銀協（法人） / 全銀協生保.csv － 全銀協（生保） / 全銀協損保.csv － 全銀協（損保） / 確認すること / アップロードがエラーなく完了すること / 抽象化 / 横浜銀行側のユーザで、横浜が使うリストを登録できるか / 結果 / 2026/9/28 OK / 指摘のやりとり / ・警察庁（IB）リストは廃止のため削除（池田） / ・「警察庁（個人）」のアップロード実施者が / 「リスク管理部門（役席）」ではなく「L&F管理者（リスク管理）」だった / → テストとしては問題なし（阿部） / ・「全銀協（損保）」の画面エビデンスが無かった → 追加 | I3: あり
A4: 3 | B4: 01_本人確認 | C4: 03 | D4: リストアップロード－L&F | E4: LF_ADMIN_RISK（会社コード0138）でログイン / リスト管理－リストアップロード画面から / Bファイル C情報.csv － BファイルC情報 / 確認すること / アップロードがエラーなく完了すること / 抽象化 / L&F側のユーザで、L&F固有のリスト（BファイルC情報）を登録できるか / 結果 / 2026/9/28 OK | H4: A-13 | I4: あり | J4: 整理メモの対応表より A-13
A5: 4 | B5: 01_本人確認 | C5: 04 | D5: タスク実行－リスト作成 | E5: タスクスケジューラから 11_リスト作成処理 を実行 / 確認すること / 「11_リスト作成処理」「12_リスト反映処理」の2タスクが正常終了 / イベントビューアにエラーログがない / C:\LogFiles\%PC_NAME%\TaskTrg_YYYYMMDDHHII.log にエラーログがない / 抽象化 / リスト作成→リスト反映が、イベントID連携で自動で流れるか / 結果 / 2026/9/28 OK / 指摘のやりとり / ・TaskTarget → TaskTrg に表記修正 / ・「12_リスト反映処理」のエビデンス（TaskTrgログ）が無い → 追加 / ・「11_リスト作成処理」でイベントID発行 → 自動でタスク実行されている | I5: あり
A6: 5 | B6: 01_本人確認 | C6: 05 | D6: タスク実行－環境初期化 | E6: ①システム時間を午前2時に設定 / ②タスクスケジューラから 01_環境初期化処理 を実行 / ③システム時間をもとに戻す / 確認すること / 下記8処理が正常終了すること / 01_環境初期化処理 / 02_全量フィルタリング処理 / 03_対象ファイル到着時間チェック処理 / 04_ユーザー情報取込処理 / 05_差分CIFバッチフィルタリング処理 / 06_検索対象者一覧バッチフィルタリング処理 / 16_AIスコアリング処理 / 08_バッチフィルタリング後処理 / イベントビューア／ログファイルにエラーログがないこと / 抽象化 / 夜間バッチ一式が通しで流れるか / 結果 / 2026/9/28 OK | I6: あり
A7: 6 | B7: 01_本人確認 | C7: 06 | D7: Web画面ログイン | E7: http://サーバIP:9080/aml-web/ に YOKOHAMA_OTHER_ADMIN でログイン | F7: ログインできること OK | I7: あり
A8: 7 | B8: 01_本人確認 | C8: 07 | D8: 本人確認 | E8: 左メニュー「本人確認－本人確認」をクリック | F8: 本人確認入力画面が表示される OK | I8: あり
A9: 8 | B9: 01_本人確認 | C9: 08 | D9: フィルタリング実行（ヒットリスト無） | E9: 個人・法人区分：法人／名称：えるえふ太郎花子（赤字修正あり） | F9: 画面上部に「[AMLHKHK01M101]該当するリストはありません。」 / が表示され、判定画面に遷移しない OK / 抽象化 : ヒットしない時に判定画面へ行かないこと（異常系） | I9: あり
A10: 9 | B10: 01_本人確認 | C10: 09 | D10: フィルタリング実行（ヒットリスト有） | E10: 個人・法人区分：法人／名称：横浜花子 / 名称（フリガナ）：ヨコハマハナコ ←赤字追加 / ※警察庁（個人・法人）リストヒットのため条件追加 ←赤字 | F10: 判定画面が表示され、該当リスト一覧に下記がヒットすること / OFAC / 財務省 / JCIF PEPs / 警察庁（個人）/ 警察庁（法人）/ ~~警察庁（IB）~~ ←赤字取消 / 全銀協（個人）/ 全銀協（法人） / DJ OFAC・企業リスト / DJ 船舶リスト / DJ 外国PEPs / DJ 国内PEPs / 全銀協（生保）/ 全銀協（損保） / 行内要注意情報：リスト情報が表示されないこと ←赤字 / 下記は表示されないこと / ~~行内要注意情報~~ ←赤字取消 / BファイルC情報 / OK / 抽象化 : どのリストがヒットし、どのリストが出ないかを1件ずつ検証 / 特に「BファイルC情報が表示されないこと」は / A-04（横浜ではBFILE_CINFOを除く）の直接の裏付け。 | H10: A-04／A-05 | I10: あり | J10: ★重要 / これは「動作確認」ではなく 設定値の検証。 / 整理メモの対応表より A-05
A11: 10 | B11: 01_本人確認 | C11: 10 | D11: 本人確認仕掛照会 | E11: 左メニュー「本人確認－本人確認仕掛照会」をクリック | F11: 仕掛中一覧画面が表示される OK | I11: あり
A12: 11 | B12: 01_本人確認 | C12: 11 | D12: 検索 | E12: 入力日：YYYYMMDD〜当日（項番3を実行した日をFromに設定） | F12: 検索結果が表示される / ※仕掛照会では「検索」押下前でも仕掛中レコードは表示される / ~~えるえふ太郎が検索結果に含まれない~~ ←赤字取消 / 自部店のみで、横浜銀行他部店・L&F部店が表示されないこと ←赤字 / OK / 抽象化 : 部店スコープ（自部店のデータしか見えないこと） / ※ A-06「部店ごとのリストの使い分けは行わない」とは別の話。 / あちらは“使うリスト”、こちらは“見えるデータ”。混同注意。 | H12: A-06 | I12: あり
A13: 12 | B13: 01_本人確認 | C13: 12 | D13: 結果選択 | E13: 検索結果の左の「判定」ボタンをクリック | F13: 判定画面が表示され、該当リスト一覧に下記がヒットすること / （09 と同じ14リスト） / 行内要注意情報 ←赤字で“表示される側”に移動 / 下記は表示されないこと / ~~行内要注意情報~~ ←赤字取消 / BファイルC情報 / OK / 抽象化 : 09 と同じ検証を、仕掛照会経由のルートでも行う | H13: A-04／A-05 | I13: あり | J13: ★重要 / ここでも BファイルC情報が表示されないこと を確認 → A-04 / 整理メモの対応表より A-05
A14: 13 | B14: 01_本人確認 | C14: 13 | D14: ログアウト | E14: 画面右上の「ログアウト」アイコンをクリック | F14: ログイン画面が表示される OK | I14: あり
A15: 14 | B15: 01_本人確認 | C15: 14 | D15: Web画面ログイン | I15: あり
A16: 15 | B16: 01_本人確認 | C16: 15 | D16: 本人確認 | I16: あり
A17: 16 | B17: 01_本人確認 | C17: 16 | D17: フィルタリング実行（無） | I17: あり
A18: 17 | B18: 01_本人確認 | C18: 17 | D18: フィルタリング実行（有） | E18: → 06〜13（YOKOHAMA_OTHER_ADMIN）とまったく同じ流れを、一般ユーザで繰り返している。 | F18: も同一。ヒットするリストも同じ14件、 / 「BファイルC情報」は表示されないこと も同じ。 / すべて 2026/9/28 OK ／ 再鑑 OK | H18: A-04／A-05 | I18: あり | J18: 整理メモの対応表より A-04・A-05
A19: 18 | B19: 01_本人確認 | C19: 18 | D19: 仕掛照会 | E19: → 06〜13（YOKOHAMA_OTHER_ADMIN）とまったく同じ流れを、一般ユーザで繰り返している。 | F19: も同一。ヒットするリストも同じ14件、 / 「BファイルC情報」は表示されないこと も同じ。 / すべて 2026/9/28 OK ／ 再鑑 OK | I19: あり
A20: 19 | B20: 01_本人確認 | C20: 19 | D20: 検索 | E20: → 06〜13（YOKOHAMA_OTHER_ADMIN）とまったく同じ流れを、一般ユーザで繰り返している。 | F20: も同一。ヒットするリストも同じ14件、 / 「BファイルC情報」は表示されないこと も同じ。 / すべて 2026/9/28 OK ／ 再鑑 OK | I20: あり
A21: 20 | B21: 01_本人確認 | C21: 20 | D21: 結果選択 | E21: → 06〜13（YOKOHAMA_OTHER_ADMIN）とまったく同じ流れを、一般ユーザで繰り返している。 | F21: も同一。ヒットするリストも同じ14件、 / 「BファイルC情報」は表示されないこと も同じ。 / すべて 2026/9/28 OK ／ 再鑑 OK | H21: A-04／A-05 | I21: あり | J21: 整理メモの対応表より A-04・A-05
A22: 21 | B22: 01_本人確認 | C22: 21 | D22: ログアウト | E22: → 06〜13（YOKOHAMA_OTHER_ADMIN）とまったく同じ流れを、一般ユーザで繰り返している。 | F22: も同一。ヒットするリストも同じ14件、 / 「BファイルC情報」は表示されないこと も同じ。 / すべて 2026/9/28 OK ／ 再鑑 OK | I22: あり
A23: 22 | B23: 01_本人確認 | C23: 22 | D23: Web画面ログイン | E23: LF_ADMIN_RISK（会社コード 0138）でログイン | F23: ログインできること OK | H23: A-14 | I23: あり | J23: 整理メモの対応表より A-14
A24: 23 | B24: 01_本人確認 | C24: 23 | D24: メニュー確認 | E24: 左側のメニューを確認（出ていなければヘッダー「Oculus-filter」右の「≡」） | F24: 「本人確認」に下記が表示されていること / 本人確認 / 本人確認仕掛照会 / 判定履歴照会 / OK / 抽象化 : そのプロファイルで使えるメニューが正しいか / 「権限 ＝ 見えるメニュー」を列挙して確認している。 | H24: A-14 | I24: あり | J24: ★重要・新しい型 / これは A-14（L&F管理者の権限を設定する）の直接の検証。
A25: 24 | B25: 01_本人確認 | C25: 24 | D25: 本人確認 | E25: 左メニュー「本人確認－本人確認」 OK | I25: あり
A26: 25 | B26: 01_本人確認 | C26: 25 | D26: フィルタリング実行（ヒットリスト無） | E26: 法人／名称：横浜花子太郎（赤字修正あり） | F26: 「該当するリストはありません。」が表示され、判定画面に遷移しない OK / ※ L&F のプロファイルでは「横浜」側の人物にヒットしない、という作り。 | I26: あり
A27: 26 | B27: 01_本人確認 | C27: 26 | D27: フィルタリング実行（ヒットリスト有） | E27: 法人／名称：えるえふ太郎 / 名称（フリガナ）：エルエフタロウ ←赤字追加 / ※警視庁（個人・法人）リストヒットのため条件追加 ←赤字 | F27: 該当リスト一覧に下記が表示されること / OFAC / 警察庁（個人）/ 警察庁（法人）/ ~~警察庁（IB）~~ ←赤字取消 / 全銀協（個人）/ 全銀協（法人） / DJ 外国PEPs / DJ 国内PEPs / 全銀協（生保）/ 全銀協（損保） / 行内要注意情報 / BファイルC情報 ← L&Fでは表示される / DJ OFAC/企業リスト ←赤字追加 / 下記は表示されないこと / 財務省 / JCIF PEPs / DJ 船舶リスト / OK / ヒアリング A-05 / 「L&F横浜店では、MOF、JPI、DJ_SHIPSを除く対象リストを利用する」 / ケース26 の「表示されないこと」 / 財務省（＝MOF）/ JCIF PEPs（＝JPI）/ DJ 船舶リスト（＝DJ_SHIPS） / → 3つとも一致。落とし込みができている。 / 横浜（ケース09/12/17/20）では表示されない。 / → A-04 と A-05 が、同じ人物・同じ画面で裏表の確認になっている。 | H27: A-04／A-05／A-13 | I27: あり | J27: ★★ 最重要 / A-05 と完全一致 / あわせて BファイルC情報 が L&F では表示される。 / 整理メモの対応表より A-13
A28: 27 | B28: 01_本人確認 | C28: 27 | D28: フィルタリング結果確認 | E28: 判定画面の該当リスト一覧から リスト：BファイルC情報 のレコードを選び、 / 画面右側のリスト情報枠で「どの項目が赤字＋太字で強調されるか」を確認。 / ※CIFをもとに検索を実施する ←赤字 / ケース レコード番号 強調される項目 / 27 LF00000001 名称 / フリガナ / 生年月日 / 抽象化 : BファイルC情報の照合項目（名称・フリガナ・生年月日）が / レコードごとに正しくヒット判定されるか / すべて 2026/9/28 OK / 照合に使う項目の組み合わせを7パターンで網羅している。 | H28: A-13 | I28: あり | J28: ★重要・新しい型 / A-13（BファイルC情報のリスト基本情報を設定する）の裏付け。
A29: 28 | B29: 01_本人確認 | C29: 28 | D29: フィルタリング結果確認 | E29: 判定画面の該当リスト一覧から リスト：BファイルC情報 のレコードを選び、 / 画面右側のリスト情報枠で「どの項目が赤字＋太字で強調されるか」を確認。 / ※CIFをもとに検索を実施する ←赤字 / ケース レコード番号 強調される項目 / 28 LF00000002 名称 / 生年月日 / 抽象化 : BファイルC情報の照合項目（名称・フリガナ・生年月日）が / レコードごとに正しくヒット判定されるか / すべて 2026/9/28 OK / 照合に使う項目の組み合わせを7パターンで網羅している。 | H29: A-13 | I29: あり | J29: ★重要・新しい型 / A-13（BファイルC情報のリスト基本情報を設定する）の裏付け。
A30: 29 | B30: 01_本人確認 | C30: 29 | D30: フィルタリング結果確認 | E30: 判定画面の該当リスト一覧から リスト：BファイルC情報 のレコードを選び、 / 画面右側のリスト情報枠で「どの項目が赤字＋太字で強調されるか」を確認。 / ※CIFをもとに検索を実施する ←赤字 / ケース レコード番号 強調される項目 / 29 LF00000003 名称 / 生年月日 / 抽象化 : BファイルC情報の照合項目（名称・フリガナ・生年月日）が / レコードごとに正しくヒット判定されるか / すべて 2026/9/28 OK / 照合に使う項目の組み合わせを7パターンで網羅している。 | H30: A-13 | I30: あり | J30: ★重要・新しい型 / A-13（BファイルC情報のリスト基本情報を設定する）の裏付け。
A31: 30 | B31: 01_本人確認 | C31: 30 | D31: フィルタリング結果確認 | E31: 判定画面の該当リスト一覧から リスト：BファイルC情報 のレコードを選び、 / 画面右側のリスト情報枠で「どの項目が赤字＋太字で強調されるか」を確認。 / ※CIFをもとに検索を実施する ←赤字 / ケース レコード番号 強調される項目 / 30 LF00000004 ~~フリガナ~~（赤字取消）/ 生年月日 / 抽象化 : BファイルC情報の照合項目（名称・フリガナ・生年月日）が / レコードごとに正しくヒット判定されるか / すべて 2026/9/28 OK / 照合に使う項目の組み合わせを7パターンで網羅している。 | H31: A-13 | I31: あり | J31: ★重要・新しい型 / A-13（BファイルC情報のリスト基本情報を設定する）の裏付け。
A32: 31 | B32: 01_本人確認 | C32: 31 | D32: フィルタリング結果確認 | E32: 判定画面の該当リスト一覧から リスト：BファイルC情報 のレコードを選び、 / 画面右側のリスト情報枠で「どの項目が赤字＋太字で強調されるか」を確認。 / ※CIFをもとに検索を実施する ←赤字 / ケース レコード番号 強調される項目 / 31 LF00000007 フリガナ / 生年月日 / 抽象化 : BファイルC情報の照合項目（名称・フリガナ・生年月日）が / レコードごとに正しくヒット判定されるか / すべて 2026/9/28 OK / 照合に使う項目の組み合わせを7パターンで網羅している。 / ケース レコード番号 強調される項目 / 31 LF00000007 フリガナ / 生年月日 / → 27〜35 の 9ケースで、BファイルC情報の照合項目を網羅。 / 名称／フリガナ／生年月日 の組み合わせを一通り確認している。 | H32: A-13 | I32: あり | J32: ★重要・新しい型 / フィルタリング結果確認（27〜30 の続き） / A-13（BファイルC情報のリスト基本情報を設定する）の裏付け。
A33: 32 | B33: 01_本人確認 | C33: 32 | D33: フィルタリング結果確認 | E33: 判定画面の該当リスト一覧から リスト：BファイルC情報 のレコードを選び、 / 画面右側のリスト情報枠で「どの項目が赤字＋太字で強調されるか」を確認。 / ※CIFをもとに検索を実施する ←赤字 / ケース レコード番号 強調される項目 / 32 LF00000019 名称 / フリガナ / 抽象化 : BファイルC情報の照合項目（名称・フリガナ・生年月日）が / レコードごとに正しくヒット判定されるか / すべて 2026/9/28 OK / 照合に使う項目の組み合わせを7パターンで網羅している。 / ケース レコード番号 強調される項目 / 32 LF00000019 名称 / フリガナ / → 27〜35 の 9ケースで、BファイルC情報の照合項目を網羅。 / 名称／フリガナ／生年月日 の組み合わせを一通り確認している。 | H33: A-13 | I33: あり | J33: ★重要・新しい型 / フィルタリング結果確認（27〜30 の続き） / A-13（BファイルC情報のリスト基本情報を設定する）の裏付け。
A34: 33 | B34: 01_本人確認 | C34: 33 | D34: フィルタリング結果確認 | E34: 判定画面の該当リスト一覧から リスト：BファイルC情報 のレコードを選び、 / 画面右側のリスト情報枠で「どの項目が赤字＋太字で強調されるか」を確認。 / ※CIFをもとに検索を実施する ←赤字 / ケース レコード番号 強調される項目 / 33 LF00000020 名称 / 抽象化 : BファイルC情報の照合項目（名称・フリガナ・生年月日）が / レコードごとに正しくヒット判定されるか / すべて 2026/9/28 OK / 照合に使う項目の組み合わせを7パターンで網羅している。 / ケース レコード番号 強調される項目 / 33 LF00000020 名称 / → 27〜35 の 9ケースで、BファイルC情報の照合項目を網羅。 / 名称／フリガナ／生年月日 の組み合わせを一通り確認している。 | H34: A-13 | I34: あり | J34: ★重要・新しい型 / フィルタリング結果確認（27〜30 の続き） / A-13（BファイルC情報のリスト基本情報を設定する）の裏付け。
A35: 34 | B35: 01_本人確認 | C35: 34 | D35: フィルタリング結果確認（27〜30 の続き） | E35: ケース レコード番号 強調される項目 / 34 LF00000021 名称 / → 27〜35 の 9ケースで、BファイルC情報の照合項目を網羅。 / 名称／フリガナ／生年月日 の組み合わせを一通り確認している。 | H35: A-13 | I35: あり | J35: 整理メモの対応表より A-13
A36: 35 | B36: 01_本人確認 | C36: 35 | D36: フィルタリング結果確認（27〜30 の続き） | E36: ケース レコード番号 強調される項目 / 35 LF00000025 フリガナ / → 27〜35 の 9ケースで、BファイルC情報の照合項目を網羅。 / 名称／フリガナ／生年月日 の組み合わせを一通り確認している。 | H36: A-13 | I36: あり | J36: 整理メモの対応表より A-13
A37: 36 | B37: 01_本人確認 | C37: 36 | D37: 本人確認仕掛照会 | G37: OK | I37: あり
A38: 37 | B38: 01_本人確認 | C38: 37 | D38: 検索 | F38: 検索結果が表示される / 横浜花子が検索結果に含まれない / OK / → L&Fプロファイルからは横浜のデータが見えない（部店スコープ） | I38: あり
A39: 38 | B39: 01_本人確認 | C39: 38 | D39: CSV出力 | E39: 「CSV出力」を押下 → 検索結果がCSV形式でダウンロードされる OK | I39: あり
A40: 39 | B40: 01_本人確認 | C40: 39 | D40: 結果選択 | F40: 該当リスト一覧に 26 と同じ顔ぶれが表示されること / ~~警察庁（IB）2026/06廃止の為非表示~~ ←赤字で理由付き / 下記は表示されないこと / 財務省 / JCIF PEPs / DJ 船舶リスト / OK / → A-05 の再確認（別ルート） | H40: A-04／A-05 | I40: あり | J40: 警察庁（IB）の削除理由が「2026/06 廃止の為非表示」と明記された。 / 整理メモの対応表より A-04
...
